Workbook

Sheet Data
A1: ts | B1: board_id | C1: color | D1: run_id | E1: volt_set | F1: volt_meas | G1: intensity | H1: kick_pc | I1: kick_ms | J1: phase | K1: measured | L1: skip_reason | M1: t_on_ms | N1: t_rising_ms | O1: t_dead_ms | P1: on_ms | Q1: en2_ms | R1: flash | S1: peak_mA | T1: settled_mA | U1: ldr_settled_V | V1: valid | W1: error | X1: pass | Y1: fail_reason | Z1: on_min | AA1: flash_max | AB1: current_min
A2: 2026-09-24 12:07:58 | B2: MLLB_000_y1.0.3 | C2: WHITE | D2: v4_white_MLLB_000_y103_0924 | E2: 4.2 | F2: 4.2 | G2: 6 | H2: 100 | I2: 12 | J2: kaba | K2: TRUE | M2: 198 | N2: 50 | O2: 170 | P2: 804 | Q2: 1002 | R2: 1.096 | S2: 10.536 | T2: 9.617 | U2: 0.778 | V2: TRUE | X2: FALSE | Y2: ON | Z2: 935 | AA2: 2.5 | AB2: 9.5
A3: 2026-09-24 12:08:14 | B3: MLLB_000_y1.0.3 | C3: WHITE | D3: v4_white_MLLB_000_y103_0924 | E3: 4.2 | F3: 4.2 | G3: 6 | H3: 100 | I3: 16 | J3: kaba | K3: TRUE | M3: 112 | N3: 48 | O3: 84 | P3: 890 | Q3: 1002 | R3: 1.092 | S3: 10.508 | T3: 9.623 | U3: 0.7781 | V3: TRUE | X3: FALSE | Y3: ON | Z3: 935 | AA3: 2.5 | AB3: 9.5
A4: 2026-09-24 12:08:30 | B4: MLLB_000_y1.0.3 | C4: WHITE | D4: v4_white_MLLB_000_y103_0924 | E4: 4.2 | F4: 4.2 | G4: 6 | H4: 100 | I4: 20 | J4: kaba | K4: TRUE | M4: 28 | N4: 30 | O4: 8 | P4: 974 | Q4: 1002 | R4: 1.09 | S4: 10.511 | T4: 9.646 | U4: 0.7779 | V4: TRUE | X4: TRUE | Z4: 935 | AA4: 2.5 | AB4: 9.5
A5: 2026-09-24 12:08:46 | B5: MLLB_000_y1.0.3 | C5: WHITE | D5: v4_white_MLLB_000_y103_0924 | E5: 4.2 | F5: 4.2 | G5: 6 | H5: 100 | I5: 24 | J5: kaba | K5: TRUE | M5: 28 | N5: 32 | O5: 6 | P5: 974 | Q5: 1002 | R5: 8.335 | S5: 80.543 | T5: 9.663 | U5: 0.7782 | V5: TRUE | X5: FALSE | Y5: FLAS | Z5: 935 | AA5: 2.5 | AB5: 9.5
A6: 2026-09-24 12:09:02 | B6: MLLB_000_y1.0.3 | C6: WHITE | D6: v4_white_MLLB_000_y103_0924 | E6: 4.2 | F6: 4.2 | G6: 6 | H6: 100 | I6: 17 | J6: ince | K6: TRUE | M6: 90 | N6: 50 | O6: 62 | P6: 912 | Q6: 1002 | R6: 1.098 | S6: 10.6 | T6: 9.65 | U6: 0.778 | V6: TRUE | X6: FALSE | Y6: ON | Z6: 935 | AA6: 2.5 | AB6: 9.5
A7: 2026-09-24 12:09:18 | B7: MLLB_000_y1.0.3 | C7: WHITE | D7: v4_white_MLLB_000_y103_0924 | E7: 4.2 | F7: 4.2 | G7: 6 | H7: 100 | I7: 18 | J7: ince | K7: TRUE | M7: 66 | N7: 50 | O7: 38 | P7: 936 | Q7: 1002 | R7: 1.091 | S7: 10.524 | T7: 9.65 | U7: 0.7777 | V7: TRUE | X7: TRUE | Z7: 935 | AA7: 2.5 | AB7: 9.5
A8: 2026-09-24 12:09:34 | B8: MLLB_000_y1.0.3 | C8: WHITE | D8: v4_white_MLLB_000_y103_0924 | E8: 4.2 | F8: 4.2 | G8: 6 | H8: 100 | I8: 19 | J8: ince | K8: TRUE | M8: 44 | N8: 48 | O8: 14 | P8: 958 | Q8: 1002 | R8: 1.1 | S8: 10.6 | T8: 9.634 | U8: 0.7772 | V8: TRUE | X8: TRUE | Z8: 935 | AA8: 2.5 | AB8: 9.5
A9: 2026-09-24 12:09:50 | B9: MLLB_000_y1.0.3 | C9: WHITE | D9: v4_white_MLLB_000_y103_0924 | E9: 4.2 | F9: 4.2 | G9: 6 | H9: 100 | I9: 21 | J9: ince | K9: TRUE | M9: 28 | N9: 32 | O9: 6 | P9: 974 | Q9: 1002 | R9: 2.471 | S9: 23.808 | T9: 9.636 | U9: 0.7783 | V9: TRUE | X9: TRUE | Z9: 935 | AA9: 2.5 | AB9: 9.5
A10: 2026-09-24 12:10:06 | B10: MLLB_000_y1.0.3 | C10: WHITE | D10: v4_white_MLLB_000_y103_0924 | E10: 4.2 | F10: 4.2 | G10: 6 | H10: 100 | I10: 22 | J10: ince | K10: TRUE | M10: 28 | N10: 32 | O10: 6 | P10: 974 | Q10: 1002 | R10: 4.486 | S10: 43.213 | T10: 9.634 | U10: 0.7781 | V10: TRUE | X10: FALSE | Y10: FLAS | Z10: 935 | AA10: 2.5 | AB10: 9.5
A11: 2026-09-24 12:10:22 | B11: MLLB_000_y1.0.3 | C11: WHITE | D11: v4_white_MLLB_000_y103_0924 | E11: 4.2 | F11: 4.2 | G11: 6 | H11: 100 | I11: 23 | J11: ince | K11: TRUE | M11: 26 | N11: 32 | O11: 6 | P11: 976 | Q11: 1002 | R11: 6.409 | S11: 61.756 | T11: 9.636 | U11: 0.7777 | V11: TRUE | X11: FALSE | Y11: FLAS | Z11: 935 | AA11: 2.5 | AB11: 9.5
A12: 2026-09-24 12:10:22 | B12: MLLB_000_y1.0.3 | C12: WHITE | D12: v4_white_MLLB_000_y103_0924 | E12: 4.2 | F12: 4.2 | G12: 6 | H12: 100 | J12: bitti | K12: FALSE | Z12: 935 | AA12: 2.5 | AB12: 9.5
A13: 2026-09-24 12:10:38 | B13: MLLB_000_y1.0.3 | C13: WHITE | D13: v4_white_MLLB_000_y103_0924 | E13: 4.2 | F13: 4.2 | G13: 6 | H13: 80 | I13: 12 | J13: kaba | K13: TRUE | M13: 240 | N13: 44 | O13: 214 | P13: 762 | Q13: 1002 | R13: 1.104 | S13: 10.553 | T13: 9.555 | U13: 0.7774 | V13: TRUE | X13: FALSE | Y13: ON | Z13: 935 | AA13: 2.5 | AB13: 9.5
A14: 2026-09-24 12:10:54 | B14: MLLB_000_y1.0.3 | C14: WHITE | D14: v4_white_MLLB_000_y103_0924 | E14: 4.2 | F14: 4.2 | G14: 6 | H14: 80 | I14: 16 | J14: kaba | K14: TRUE | M14: 170 | N14: 50 | O14: 142 | P14: 832 | Q14: 1002 | R14: 1.095 | S14: 10.514 | T14: 9.599 | U14: 0.7783 | V14: TRUE | X14: FALSE | Y14: ON | Z14: 935 | AA14: 2.5 | AB14: 9.5
A15: 2026-09-24 12:11:10 | B15: MLLB_000_y1.0.3 | C15: WHITE | D15: v4_white_MLLB_000_y103_0924 | E15: 4.2 | F15: 4.2 | G15: 6 | H15: 80 | I15: 20 | J15: kaba | K15: TRUE | M15: 100 | N15: 48 | O15: 72 | P15: 902 | Q15: 1002 | R15: 1.093 | S15: 10.533 | T15: 9.641 | U15: 0.7773 | V15: TRUE | X15: FALSE | Y15: ON | Z15: 935 | AA15: 2.5 | AB15: 9.5
A16: 2026-09-24 12:11:26 | B16: MLLB_000_y1.0.3 | C16: WHITE | D16: v4_white_MLLB_000_y103_0924 | E16: 4.2 | F16: 4.2 | G16: 6 | H16: 80 | I16: 24 | J16: kaba | K16: TRUE | M16: 30 | N16: 32 | O16: 10 | P16: 972 | Q16: 1002 | R16: 1.099 | S16: 10.6 | T16: 9.645 | U16: 0.7778 | V16: TRUE | X16: TRUE | Z16: 935 | AA16: 2.5 | AB16: 9.5
A17: 2026-09-24 12:11:42 | B17: MLLB_000_y1.0.3 | C17: WHITE | D17: v4_white_MLLB_000_y103_0924 | E17: 4.2 | F17: 4.2 | G17: 6 | H17: 80 | I17: 28 | J17: kaba | K17: TRUE | M17: 30 | N17: 32 | O17: 10 | P17: 972 | Q17: 1002 | R17: 6.427 | S17: 61.927 | T17: 9.636 | U17: 0.7779 | V17: TRUE | X17: FALSE | Y17: FLAS | Z17: 935 | AA17: 2.5 | AB17: 9.5
A18: 2026-09-24 12:11:58 | B18: MLLB_000_y1.0.3 | C18: WHITE | D18: v4_white_MLLB_000_y103_0924 | E18: 4.2 | F18: 4.2 | G18: 6 | H18: 80 | I18: 21 | J18: ince | K18: TRUE | M18: 82 | N18: 44 | O18: 54 | P18: 920 | Q18: 1002 | R18: 1.094 | S18: 10.554 | T18: 9.648 | U18: 0.7775 | V18: TRUE | X18: FALSE | Y18: ON | Z18: 935 | AA18: 2.5 | AB18: 9.5
A19: 2026-09-24 12:12:14 | B19: MLLB_000_y1.0.3 | C19: WHITE | D19: v4_white_MLLB_000_y103_0924 | E19: 4.2 | F19: 4.2 | G19: 6 | H19: 80 | I19: 22 | J19: ince | K19: TRUE | M19: 64 | N19: 50 | O19: 34 | P19: 938 | Q19: 1002 | R19: 1.091 | S19: 10.511 | T19: 9.632 | U19: 0.7772 | V19: TRUE | X19: TRUE | Z19: 935 | AA19: 2.5 | AB19: 9.5
A20: 2026-09-24 12:12:30 | B20: MLLB_000_y1.0.3 | C20: WHITE | D20: v4_white_MLLB_000_y103_0924 | E20: 4.2 | F20: 4.2 | G20: 6 | H20: 80 | I20: 23 | J20: ince | K20: TRUE | M20: 42 | N20: 50 | O20: 14 | P20: 960 | Q20: 1002 | R20: 1.093 | S20: 10.524 | T20: 9.632 | U20: 0.7771 | V20: TRUE | X20: TRUE | Z20: 935 | AA20: 2.5 | AB20: 9.5
A21: 2026-09-24 12:12:46 | B21: MLLB_000_y1.0.3 | C21: WHITE | D21: v4_white_MLLB_000_y103_0924 | E21: 4.2 | F21: 4.2 | G21: 6 | H21: 80 | I21: 25 | J21: ince | K21: TRUE | M21: 32 | N21: 30 | O21: 12 | P21: 970 | Q21: 1002 | R21: 2.044 | S21: 19.692 | T21: 9.632 | U21: 0.7772 | V21: TRUE | X21: TRUE | Z21: 935 | AA21: 2.5 | AB21: 9.5
A22: 2026-09-24 12:13:02 | B22: MLLB_000_y1.0.3 | C22: WHITE | D22: v4_white_MLLB_000_y103_0924 | E22: 4.2 | F22: 4.2 | G22: 6 | H22: 80 | I22: 26 | J22: ince | K22: TRUE | M22: 30 | N22: 32 | O22: 10 | P22: 972 | Q22: 1002 | R22: 3.508 | S22: 33.814 | T22: 9.64 | U22: 0.7774 | V22: TRUE | X22: FALSE | Y22: FLAS | Z22: 935 | AA22: 2.5 | AB22: 9.5
A23: 2026-09-24 12:13:18 | B23: MLLB_000_y1.0.3 | C23: WHITE | D23: v4_white_MLLB_000_y103_0924 | E23: 4.2 | F23: 4.2 | G23: 6 | H23: 80 | I23: 27 | J23: ince | K23: TRUE | M23: 30 | N23: 32 | O23: 10 | P23: 972 | Q23: 1002 | R23: 5.031 | S23: 48.565 | T23: 9.653 | U23: 0.7775 | V23: TRUE | X23: FALSE | Y23: FLAS | Z23: 935 | AA23: 2.5 | AB23: 9.5
A24: 2026-09-24 12:13:18 | B24: MLLB_000_y1.0.3 | C24: WHITE | D24: v4_white_MLLB_000_y103_0924 | E24: 4.2 | F24: 4.2 | G24: 6 | H24: 80 | J24: bitti | K24: FALSE | Z24: 935 | AA24: 2.5 | AB24: 9.5
A25: 2026-09-24 12:13:34 | B25: MLLB_000_y1.0.3 | C25: WHITE | D25: v4_white_MLLB_000_y103_0924 | E25: 4.2 | F25: 4.2 | G25: 6 | H25: 60 | I25: 12 | J25: kaba | K25: TRUE | M25: 286 | N25: 50 | O25: 258 | P25: 716 | Q25: 1002 | R25: 1.103 | S25: 10.508 | T25: 9.526 | U25: 0.7772 | V25: TRUE | X25: FALSE | Y25: ON | Z25: 935 | AA25: 2.5 | AB25: 9.5
A26: 2026-09-24 12:13:50 | B26: MLLB_000_y1.0.3 | C26: WHITE | D26: v4_white_MLLB_000_y103_0924 | E26: 4.2 | F26: 4.2 | G26: 6 | H26: 60 | I26: 16 | J26: kaba | K26: TRUE | M26: 236 | N26: 50 | O26: 206 | P26: 766 | Q26: 1002 | R26: 1.1 | S26: 10.508 | T26: 9.553 | U26: 0.7778 | V26: TRUE | X26: FALSE | Y26: ON | Z26: 935 | AA26: 2.5 | AB26: 9.5
A27: 2026-09-24 12:14:02 | B27: MLLB_000_y1.0.3 | C27: WHITE | D27: v4_white_MLLB_000_y103_0924 | E27: 4.2 | F27: 4.2 | G27: 6 | H27: 60 | I27: 20 | J27: kaba | K27: TRUE | M27: 184 | N27: 44 | O27: 158 | P27: 818 | Q27: 1002 | R27: 1.099 | S27: 10.531 | T27: 9.585 | U27: 0.7774 | V27: TRUE | X27: FALSE | Y27: ON | Z27: 935 | AA27: 2.5 | AB27: 9.5
A28: 2026-09-24 12:14:18 | B28: MLLB_000_y1.0.3 | C28: WHITE | D28: v4_white_MLLB_000_y103_0924 | E28: 4.2 | F28: 4.2 | G28: 6 | H28: 60 | I28: 24 | J28: kaba | K28: TRUE | M28: 132 | N28: 44 | O28: 106 | P28: 870 | Q28: 1002 | R28: 1.103 | S28: 10.6 | T28: 9.61 | U28: 0.7778 | V28: TRUE | X28: FALSE | Y28: ON | Z28: 935 | AA28: 2.5 | AB28: 9.5
A29: 2026-09-24 12:14:34 | B29: MLLB_000_y1.0.3 | C29: WHITE | D29: v4_white_MLLB_000_y103_0924 | E29: 4.2 | F29: 4.2 | G29: 6 | H29: 60 | I29: 28 | J29: kaba | K29: TRUE | M29: 80 | N29: 50 | O29: 50 | P29: 922 | Q29: 1002 | R29: 1.089 | S29: 10.508 | T29: 9.646 | U29: 0.7779 | V29: TRUE | X29: FALSE | Y29: ON | Z29: 935 | AA29: 2.5 | AB29: 9.5
A30: 2026-09-24 12:14:46 | B30: MLLB_000_y1.0.3 | C30: WHITE | D30: v4_white_MLLB_000_y103_0924 | E30: 4.2 | F30: 4.2 | G30: 6 | H30: 60 | I30: 32 | J30: kaba | K30: TRUE | M30: 38 | N30: 28 | O30: 18 | P30: 964 | Q30: 1002 | R30: 1.245 | S30: 12.001 | T30: 9.643 | U30: 0.7775 | V30: TRUE | X30: TRUE | Z30: 935 | AA30: 2.5 | AB30: 9.5
A31: 2026-09-24 12:15:02 | B31: MLLB_000_y1.0.3 | C31: WHITE | D31: v4_white_MLLB_000_y103_0924 | E31: 4.2 | F31: 4.2 | G31: 6 | H31: 60 | I31: 36 | J31: kaba | K31: TRUE | M31: 38 | N31: 28 | O31: 18 | P31: 964 | Q31: 1002 | R31: 5.309 | S31: 51.139 | T31: 9.632 | U31: 0.7782 | V31: TRUE | X31: FALSE | Y31: FLAS | Z31: 935 | AA31: 2.5 | AB31: 9.5
A32: 2026-09-24 12:15:18 | B32: MLLB_000_y1.0.3 | C32: WHITE | D32: v4_white_MLLB_000_y103_0924 | E32: 4.2 | F32: 4.2 | G32: 6 | H32: 60 | I32: 40 | J32: kaba | K32: TRUE | M32: 38 | N32: 28 | O32: 18 | P32: 964 | Q32: 1002 | R32: 8.569 | S32: 82.652 | T32: 9.645 | U32: 0.7775 | V32: TRUE | X32: FALSE | Y32: FLAS | Z32: 935 | AA32: 2.5 | AB32: 9.5
A33: 2026-09-24 12:15:34 | B33: MLLB_000_y1.0.3 | C33: WHITE | D33: v4_white_MLLB_000_y103_0924 | E33: 4.2 | F33: 4.2 | G33: 6 | H33: 60 | I33: 29 | J33: ince | K33: TRUE | M33: 66 | N33: 50 | O33: 38 | P33: 936 | Q33: 1002 | R33: 1.1 | S33: 10.6 | T33: 9.639 | U33: 0.7777 | V33: TRUE | X33: TRUE | Z33: 935 | AA33: 2.5 | AB33: 9.5
A34: 2026-09-24 12:15:50 | B34: MLLB_000_y1.0.3 | C34: WHITE | D34: v4_white_MLLB_000_y103_0924 | E34: 4.2 | F34: 4.2 | G34: 6 | H34: 60 | I34: 30 | J34: ince | K34: TRUE | M34: 52 | N34: 46 | O34: 24 | P34: 950 | Q34: 1002 | R34: 1.091 | S34: 10.508 | T34: 9.633 | U34: 0.7784 | V34: TRUE | X34: TRUE | Z34: 935 | AA34: 2.5 | AB34: 9.5
A35: 2026-09-24 12:16:06 | B35: MLLB_000_y1.0.3 | C35: WHITE | D35: v4_white_MLLB_000_y103_0924 | E35: 4.2 | F35: 4.2 | G35: 6 | H35: 60 | I35: 31 | J35: ince | K35: TRUE | M35: 38 | N35: 38 | O35: 18 | P35: 964 | Q35: 1002 | R35: 1.094 | S35: 10.58 | T35: 9.673 | U35: 0.7778 | V35: TRUE | X35: TRUE | Z35: 935 | AA35: 2.5 | AB35: 9.5
A36: 2026-09-24 12:16:22 | B36: MLLB_000_y1.0.3 | C36: WHITE | D36: v4_white_MLLB_000_y103_0924 | E36: 4.2 | F36: 4.2 | G36: 6 | H36: 60 | I36: 33 | J36: ince | K36: TRUE | M36: 38 | N36: 28 | O36: 18 | P36: 964 | Q36: 1002 | R36: 2.158 | S36: 20.807 | T36: 9.642 | U36: 0.778 | V36: TRUE | X36: TRUE | Z36: 935 | AA36: 2.5 | AB36: 9.5
A37: 2026-09-24 12:16:38 | B37: MLLB_000_y1.0.3 | C37: WHITE | D37: v4_white_MLLB_000_y103_0924 | E37: 4.2 | F37: 4.2 | G37: 6 | H37: 60 | I37: 34 | J37: ince | K37: TRUE | M37: 38 | N37: 28 | O37: 18 | P37: 964 | Q37: 1002 | R37: 3.235 | S37: 31.22 | T37: 9.65 | U37: 0.7776 | V37: TRUE | X37: FALSE | Y37: FLAS | Z37: 935 | AA37: 2.5 | AB37: 9.5
A38: 2026-09-24 12:16:54 | B38: MLLB_000_y1.0.3 | C38: WHITE | D38: v4_white_MLLB_000_y103_0924 | E38: 4.2 | F38: 4.2 | G38: 6 | H38: 60 | I38: 35 | J38: ince | K38: TRUE | M38: 38 | N38: 28 | O38: 18 | P38: 964 | Q38: 1002 | R38: 4.32 | S38: 41.56 | T38: 9.62 | U38: 0.7776 | V38: TRUE | X38: FALSE | Y38: FLAS | Z38: 935 | AA38: 2.5 | AB38: 9.5
A39: 2026-09-24 12:16:54 | B39: MLLB_000_y1.0.3 | C39: WHITE | D39: v4_white_MLLB_000_y103_0924 | E39: 4.2 | F39: 4.2 | G39: 6 | H39: 60 | J39: bitti | K39: FALSE | Z39: 935 | AA39: 2.5 | AB39: 9.5
A40: 2026-09-24 12:17:28 | B40: MLLB_000_y1.0.3 | C40: WHITE | D40: v4_white_MLLB_000_y103_0924 | E40: 4.2 | F40: 4.2 | G40: 7 | H40: 100 | I40: 12 | J40: kaba | K40: TRUE | M40: 162 | N40: 40 | O40: 138 | P40: 840 | Q40: 1002 | R40: 1.095 | S40: 12.995 | T40: 11.865 | U40: 0.778 | V40: TRUE | X40: FALSE | Y40: ON | Z40: 935 | AA40: 2.5 | AB40: 9.5
...

Sheet Data_new
A1: voltage | B1: intensity | C1: kick_pc | D1: kick_ms | E1: t_on_ms | F1: t_dead_ms | G1: warmup_ms | H1: on_ms | I1: real_on_ms | J1: calc_total | K1: flash | L1: settled_mA | M1: all_zero | N1: pass_warmup_on_ms | O1: pass_warmup_real_ms | P1: pass_on_ms | Q1: pass_real_on_ms | R1: .
A2: =Data!E2 | B2: =Data!G2 | C2: =Data!H2 | D2: =Data!I2 | E2: =Data!M2 | F2: =Data!O2 | G2: =E2-F2 | H2: =Data!P2 | I2: =G2+H2 | J2: =F2+G2+H2 | K2: =Data!R2 | L2: =Data!T2 | M2: =AND(E2=0,F2=0,G2=0,H2=0,I2=0,J2=0,K2=0,L2=0) | N2: =G2<=$T$6 | O2: =G2<=$T$12 | P2: =OR(AND(H2>=$T$4,K2<=$T$5,N2),M2) | Q2: =OR(AND(I2>=$T$10,K2<=$T$11,O2),M2)
A3: =Data!E3 | B3: =Data!G3 | C3: =Data!H3 | D3: =Data!I3 | E3: =Data!M3 | F3: =Data!O3 | G3: =E3-F3 | H3: =Data!P3 | I3: =G3+H3 | J3: =F3+G3+H3 | K3: =Data!R3 | L3: =Data!T3 | M3: =AND(E3=0,F3=0,G3=0,H3=0,I3=0,J3=0,K3=0,L3=0) | N3: =G3<=$T$6 | O3: =G3<=$T$12 | P3: =OR(AND(H3>=$T$4,K3<=$T$5,N3),M3) | Q3: =OR(AND(I3>=$T$10,K3<=$T$11,O3),M3)
A4: =Data!E4 | B4: =Data!G4 | C4: =Data!H4 | D4: =Data!I4 | E4: =Data!M4 | F4: =Data!O4 | G4: =E4-F4 | H4: =Data!P4 | I4: =G4+H4 | J4: =F4+G4+H4 | K4: =Data!R4 | L4: =Data!T4 | M4: =AND(E4=0,F4=0,G4=0,H4=0,I4=0,J4=0,K4=0,L4=0) | N4: =G4<=$T$6 | O4: =G4<=$T$12 | P4: =OR(AND(H4>=$T$4,K4<=$T$5,N4),M4) | Q4: =OR(AND(I4>=$T$10,K4<=$T$11,O4),M4) | S4: min on_ms | T4: 800
A5: =Data!E5 | B5: =Data!G5 | C5: =Data!H5 | D5: =Data!I5 | E5: =Data!M5 | F5: =Data!O5 | G5: =E5-F5 | H5: =Data!P5 | I5: =G5+H5 | J5: =F5+G5+H5 | K5: =Data!R5 | L5: =Data!T5 | M5: =AND(E5=0,F5=0,G5=0,H5=0,I5=0,J5=0,K5=0,L5=0) | N5: =G5<=$T$6 | O5: =G5<=$T$12 | P5: =OR(AND(H5>=$T$4,K5<=$T$5,N5),M5) | Q5: =OR(AND(I5>=$T$10,K5<=$T$11,O5),M5) | S5: max flash | T5: 3.5
A6: =Data!E6 | B6: =Data!G6 | C6: =Data!H6 | D6: =Data!I6 | E6: =Data!M6 | F6: =Data!O6 | G6: =E6-F6 | H6: =Data!P6 | I6: =G6+H6 | J6: =F6+G6+H6 | K6: =Data!R6 | L6: =Data!T6 | M6: =AND(E6=0,F6=0,G6=0,H6=0,I6=0,J6=0,K6=0,L6=0) | N6: =G6<=$T$6 | O6: =G6<=$T$12 | P6: =OR(AND(H6>=$T$4,K6<=$T$5,N6),M6) | Q6: =OR(AND(I6>=$T$10,K6<=$T$11,O6),M6) | S6: max_warmup_ms | T6: 300
A7: =Data!E7 | B7: =Data!G7 | C7: =Data!H7 | D7: =Data!I7 | E7: =Data!M7 | F7: =Data!O7 | G7: =E7-F7 | H7: =Data!P7 | I7: =G7+H7 | J7: =F7+G7+H7 | K7: =Data!R7 | L7: =Data!T7 | M7: =AND(E7=0,F7=0,G7=0,H7=0,I7=0,J7=0,K7=0,L7=0) | N7: =G7<=$T$6 | O7: =G7<=$T$12 | P7: =OR(AND(H7>=$T$4,K7<=$T$5,N7),M7) | Q7: =OR(AND(I7>=$T$10,K7<=$T$11,O7),M7) | S7: pass True | T7: {=SUMPRODUCT(((($H$2:$H$2639>=T4)*($K$2:$K$2639<=T5)*($G$2:$G$2639<=T6))+(--$M$2:$M$2639)>0)*1)} | U7: =T7/COUNT($A$2:$A$2639)
A8: =Data!E8 | B8: =Data!G8 | C8: =Data!H8 | D8: =Data!I8 | E8: =Data!M8 | F8: =Data!O8 | G8: =E8-F8 | H8: =Data!P8 | I8: =G8+H8 | J8: =F8+G8+H8 | K8: =Data!R8 | L8: =Data!T8 | M8: =AND(E8=0,F8=0,G8=0,H8=0,I8=0,J8=0,K8=0,L8=0) | N8: =G8<=$T$6 | O8: =G8<=$T$12 | P8: =OR(AND(H8>=$T$4,K8<=$T$5,N8),M8) | Q8: =OR(AND(I8>=$T$10,K8<=$T$11,O8),M8) | S8: pass False | T8: =COUNT($A$2:$A$2639)-T7 | U8: =T8/COUNT($A$2:$A$2639)
A9: =Data!E9 | B9: =Data!G9 | C9: =Data!H9 | D9: =Data!I9 | E9: =Data!M9 | F9: =Data!O9 | G9: =E9-F9 | H9: =Data!P9 | I9: =G9+H9 | J9: =F9+G9+H9 | K9: =Data!R9 | L9: =Data!T9 | M9: =AND(E9=0,F9=0,G9=0,H9=0,I9=0,J9=0,K9=0,L9=0) | N9: =G9<=$T$6 | O9: =G9<=$T$12 | P9: =OR(AND(H9>=$T$4,K9<=$T$5,N9),M9) | Q9: =OR(AND(I9>=$T$10,K9<=$T$11,O9),M9)
A10: =Data!E10 | B10: =Data!G10 | C10: =Data!H10 | D10: =Data!I10 | E10: =Data!M10 | F10: =Data!O10 | G10: =E10-F10 | H10: =Data!P10 | I10: =G10+H10 | J10: =F10+G10+H10 | K10: =Data!R10 | L10: =Data!T10 | M10: =AND(E10=0,F10=0,G10=0,H10=0,I10=0,J10=0,K10=0,L10=0) | N10: =G10<=$T$6 | O10: =G10<=$T$12 | P10: =OR(AND(H10>=$T$4,K10<=$T$5,N10),M10) | Q10: =OR(AND(I10>=$T$10,K10<=$T$11,O10),M10) | S10: min real_on_ms | T10: 800
A11: =Data!E11 | B11: =Data!G11 | C11: =Data!H11 | D11: =Data!I11 | E11: =Data!M11 | F11: =Data!O11 | G11: =E11-F11 | H11: =Data!P11 | I11: =G11+H11 | J11: =F11+G11+H11 | K11: =Data!R11 | L11: =Data!T11 | M11: =AND(E11=0,F11=0,G11=0,H11=0,I11=0,J11=0,K11=0,L11=0) | N11: =G11<=$T$6 | O11: =G11<=$T$12 | P11: =OR(AND(H11>=$T$4,K11<=$T$5,N11),M11) | Q11: =OR(AND(I11>=$T$10,K11<=$T$11,O11),M11) | S11: max flash | T11: 3.5
A12: =Data!E13 | B12: =Data!G13 | C12: =Data!H13 | D12: =Data!I13 | E12: =Data!M13 | F12: =Data!O13 | G12: =E12-F12 | H12: =Data!P13 | I12: =G12+H12 | J12: =F12+G12+H12 | K12: =Data!R13 | L12: =Data!T13 | M12: =AND(E12=0,F12=0,G12=0,H12=0,I12=0,J12=0,K12=0,L12=0) | N12: =G12<=$T$6 | O12: =G12<=$T$12 | P12: =OR(AND(H12>=$T$4,K12<=$T$5,N12),M12) | Q12: =OR(AND(I12>=$T$10,K12<=$T$11,O12),M12) | S12: max_warmup_ms | T12: 500
A13: =Data!E14 | B13: =Data!G14 | C13: =Data!H14 | D13: =Data!I14 | E13: =Data!M14 | F13: =Data!O14 | G13: =E13-F13 | H13: =Data!P14 | I13: =G13+H13 | J13: =F13+G13+H13 | K13: =Data!R14 | L13: =Data!T14 | M13: =AND(E13=0,F13=0,G13=0,H13=0,I13=0,J13=0,K13=0,L13=0) | N13: =G13<=$T$6 | O13: =G13<=$T$12 | P13: =OR(AND(H13>=$T$4,K13<=$T$5,N13),M13) | Q13: =OR(AND(I13>=$T$10,K13<=$T$11,O13),M13) | S13: pass True | T13: {=SUMPRODUCT(((($I$2:$I$2639>=T10)*($K$2:$K$2639<=T11)*($G$2:$G$2639<=T12))+(--$M$2:$M$2639)>0)*1)} | U13: =T13/COUNT($A$2:$A$2639)
A14: =Data!E15 | B14: =Data!G15 | C14: =Data!H15 | D14: =Data!I15 | E14: =Data!M15 | F14: =Data!O15 | G14: =E14-F14 | H14: =Data!P15 | I14: =G14+H14 | J14: =F14+G14+H14 | K14: =Data!R15 | L14: =Data!T15 | M14: =AND(E14=0,F14=0,G14=0,H14=0,I14=0,J14=0,K14=0,L14=0) | N14: =G14<=$T$6 | O14: =G14<=$T$12 | P14: =OR(AND(H14>=$T$4,K14<=$T$5,N14),M14) | Q14: =OR(AND(I14>=$T$10,K14<=$T$11,O14),M14) | S14: pass False | T14: =COUNT($A$2:$A$2639)-T13 | U14: =T14/COUNT($A$2:$A$2639)
A15: =Data!E16 | B15: =Data!G16 | C15: =Data!H16 | D15: =Data!I16 | E15: =Data!M16 | F15: =Data!O16 | G15: =E15-F15 | H15: =Data!P16 | I15: =G15+H15 | J15: =F15+G15+H15 | K15: =Data!R16 | L15: =Data!T16 | M15: =AND(E15=0,F15=0,G15=0,H15=0,I15=0,J15=0,K15=0,L15=0) | N15: =G15<=$T$6 | O15: =G15<=$T$12 | P15: =OR(AND(H15>=$T$4,K15<=$T$5,N15),M15) | Q15: =OR(AND(I15>=$T$10,K15<=$T$11,O15),M15)
A16: =Data!E17 | B16: =Data!G17 | C16: =Data!H17 | D16: =Data!I17 | E16: =Data!M17 | F16: =Data!O17 | G16: =E16-F16 | H16: =Data!P17 | I16: =G16+H16 | J16: =F16+G16+H16 | K16: =Data!R17 | L16: =Data!T17 | M16: =AND(E16=0,F16=0,G16=0,H16=0,I16=0,J16=0,K16=0,L16=0) | N16: =G16<=$T$6 | O16: =G16<=$T$12 | P16: =OR(AND(H16>=$T$4,K16<=$T$5,N16),M16) | Q16: =OR(AND(I16>=$T$10,K16<=$T$11,O16),M16)
A17: =Data!E18 | B17: =Data!G18 | C17: =Data!H18 | D17: =Data!I18 | E17: =Data!M18 | F17: =Data!O18 | G17: =E17-F17 | H17: =Data!P18 | I17: =G17+H17 | J17: =F17+G17+H17 | K17: =Data!R18 | L17: =Data!T18 | M17: =AND(E17=0,F17=0,G17=0,H17=0,I17=0,J17=0,K17=0,L17=0) | N17: =G17<=$T$6 | O17: =G17<=$T$12 | P17: =OR(AND(H17>=$T$4,K17<=$T$5,N17),M17) | Q17: =OR(AND(I17>=$T$10,K17<=$T$11,O17),M17)
A18: =Data!E19 | B18: =Data!G19 | C18: =Data!H19 | D18: =Data!I19 | E18: =Data!M19 | F18: =Data!O19 | G18: =E18-F18 | H18: =Data!P19 | I18: =G18+H18 | J18: =F18+G18+H18 | K18: =Data!R19 | L18: =Data!T19 | M18: =AND(E18=0,F18=0,G18=0,H18=0,I18=0,J18=0,K18=0,L18=0) | N18: =G18<=$T$6 | O18: =G18<=$T$12 | P18: =OR(AND(H18>=$T$4,K18<=$T$5,N18),M18) | Q18: =OR(AND(I18>=$T$10,K18<=$T$11,O18),M18)
A19: =Data!E20 | B19: =Data!G20 | C19: =Data!H20 | D19: =Data!I20 | E19: =Data!M20 | F19: =Data!O20 | G19: =E19-F19 | H19: =Data!P20 | I19: =G19+H19 | J19: =F19+G19+H19 | K19: =Data!R20 | L19: =Data!T20 | M19: =AND(E19=0,F19=0,G19=0,H19=0,I19=0,J19=0,K19=0,L19=0) | N19: =G19<=$T$6 | O19: =G19<=$T$12 | P19: =OR(AND(H19>=$T$4,K19<=$T$5,N19),M19) | Q19: =OR(AND(I19>=$T$10,K19<=$T$11,O19),M19)
A20: =Data!E21 | B20: =Data!G21 | C20: =Data!H21 | D20: =Data!I21 | E20: =Data!M21 | F20: =Data!O21 | G20: =E20-F20 | H20: =Data!P21 | I20: =G20+H20 | J20: =F20+G20+H20 | K20: =Data!R21 | L20: =Data!T21 | M20: =AND(E20=0,F20=0,G20=0,H20=0,I20=0,J20=0,K20=0,L20=0) | N20: =G20<=$T$6 | O20: =G20<=$T$12 | P20: =OR(AND(H20>=$T$4,K20<=$T$5,N20),M20) | Q20: =OR(AND(I20>=$T$10,K20<=$T$11,O20),M20)
A21: =Data!E22 | B21: =Data!G22 | C21: =Data!H22 | D21: =Data!I22 | E21: =Data!M22 | F21: =Data!O22 | G21: =E21-F21 | H21: =Data!P22 | I21: =G21+H21 | J21: =F21+G21+H21 | K21: =Data!R22 | L21: =Data!T22 | M21: =AND(E21=0,F21=0,G21=0,H21=0,I21=0,J21=0,K21=0,L21=0) | N21: =G21<=$T$6 | O21: =G21<=$T$12 | P21: =OR(AND(H21>=$T$4,K21<=$T$5,N21),M21) | Q21: =OR(AND(I21>=$T$10,K21<=$T$11,O21),M21)
A22: =Data!E23 | B22: =Data!G23 | C22: =Data!H23 | D22: =Data!I23 | E22: =Data!M23 | F22: =Data!O23 | G22: =E22-F22 | H22: =Data!P23 | I22: =G22+H22 | J22: =F22+G22+H22 | K22: =Data!R23 | L22: =Data!T23 | M22: =AND(E22=0,F22=0,G22=0,H22=0,I22=0,J22=0,K22=0,L22=0) | N22: =G22<=$T$6 | O22: =G22<=$T$12 | P22: =OR(AND(H22>=$T$4,K22<=$T$5,N22),M22) | Q22: =OR(AND(I22>=$T$10,K22<=$T$11,O22),M22)
A23: =Data!E25 | B23: =Data!G25 | C23: =Data!H25 | D23: =Data!I25 | E23: =Data!M25 | F23: =Data!O25 | G23: =E23-F23 | H23: =Data!P25 | I23: =G23+H23 | J23: =F23+G23+H23 | K23: =Data!R25 | L23: =Data!T25 | M23: =AND(E23=0,F23=0,G23=0,H23=0,I23=0,J23=0,K23=0,L23=0) | N23: =G23<=$T$6 | O23: =G23<=$T$12 | P23: =OR(AND(H23>=$T$4,K23<=$T$5,N23),M23) | Q23: =OR(AND(I23>=$T$10,K23<=$T$11,O23),M23)
A24: =Data!E26 | B24: =Data!G26 | C24: =Data!H26 | D24: =Data!I26 | E24: =Data!M26 | F24: =Data!O26 | G24: =E24-F24 | H24: =Data!P26 | I24: =G24+H24 | J24: =F24+G24+H24 | K24: =Data!R26 | L24: =Data!T26 | M24: =AND(E24=0,F24=0,G24=0,H24=0,I24=0,J24=0,K24=0,L24=0) | N24: =G24<=$T$6 | O24: =G24<=$T$12 | P24: =OR(AND(H24>=$T$4,K24<=$T$5,N24),M24) | Q24: =OR(AND(I24>=$T$10,K24<=$T$11,O24),M24)
A25: =Data!E27 | B25: =Data!G27 | C25: =Data!H27 | D25: =Data!I27 | E25: =Data!M27 | F25: =Data!O27 | G25: =E25-F25 | H25: =Data!P27 | I25: =G25+H25 | J25: =F25+G25+H25 | K25: =Data!R27 | L25: =Data!T27 | M25: =AND(E25=0,F25=0,G25=0,H25=0,I25=0,J25=0,K25=0,L25=0) | N25: =G25<=$T$6 | O25: =G25<=$T$12 | P25: =OR(AND(H25>=$T$4,K25<=$T$5,N25),M25) | Q25: =OR(AND(I25>=$T$10,K25<=$T$11,O25),M25)
A26: =Data!E28 | B26: =Data!G28 | C26: =Data!H28 | D26: =Data!I28 | E26: =Data!M28 | F26: =Data!O28 | G26: =E26-F26 | H26: =Data!P28 | I26: =G26+H26 | J26: =F26+G26+H26 | K26: =Data!R28 | L26: =Data!T28 | M26: =AND(E26=0,F26=0,G26=0,H26=0,I26=0,J26=0,K26=0,L26=0) | N26: =G26<=$T$6 | O26: =G26<=$T$12 | P26: =OR(AND(H26>=$T$4,K26<=$T$5,N26),M26) | Q26: =OR(AND(I26>=$T$10,K26<=$T$11,O26),M26)
A27: =Data!E29 | B27: =Data!G29 | C27: =Data!H29 | D27: =Data!I29 | E27: =Data!M29 | F27: =Data!O29 | G27: =E27-F27 | H27: =Data!P29 | I27: =G27+H27 | J27: =F27+G27+H27 | K27: =Data!R29 | L27: =Data!T29 | M27: =AND(E27=0,F27=0,G27=0,H27=0,I27=0,J27=0,K27=0,L27=0) | N27: =G27<=$T$6 | O27: =G27<=$T$12 | P27: =OR(AND(H27>=$T$4,K27<=$T$5,N27),M27) | Q27: =OR(AND(I27>=$T$10,K27<=$T$11,O27),M27)
A28: =Data!E30 | B28: =Data!G30 | C28: =Data!H30 | D28: =Data!I30 | E28: =Data!M30 | F28: =Data!O30 | G28: =E28-F28 | H28: =Data!P30 | I28: =G28+H28 | J28: =F28+G28+H28 | K28: =Data!R30 | L28: =Data!T30 | M28: =AND(E28=0,F28=0,G28=0,H28=0,I28=0,J28=0,K28=0,L28=0) | N28: =G28<=$T$6 | O28: =G28<=$T$12 | P28: =OR(AND(H28>=$T$4,K28<=$T$5,N28),M28) | Q28: =OR(AND(I28>=$T$10,K28<=$T$11,O28),M28)
A29: =Data!E31 | B29: =Data!G31 | C29: =Data!H31 | D29: =Data!I31 | E29: =Data!M31 | F29: =Data!O31 | G29: =E29-F29 | H29: =Data!P31 | I29: =G29+H29 | J29: =F29+G29+H29 | K29: =Data!R31 | L29: =Data!T31 | M29: =AND(E29=0,F29=0,G29=0,H29=0,I29=0,J29=0,K29=0,L29=0) | N29: =G29<=$T$6 | O29: =G29<=$T$12 | P29: =OR(AND(H29>=$T$4,K29<=$T$5,N29),M29) | Q29: =OR(AND(I29>=$T$10,K29<=$T$11,O29),M29)
A30: =Data!E32 | B30: =Data!G32 | C30: =Data!H32 | D30: =Data!I32 | E30: =Data!M32 | F30: =Data!O32 | G30: =E30-F30 | H30: =Data!P32 | I30: =G30+H30 | J30: =F30+G30+H30 | K30: =Data!R32 | L30: =Data!T32 | M30: =AND(E30=0,F30=0,G30=0,H30=0,I30=0,J30=0,K30=0,L30=0) | N30: =G30<=$T$6 | O30: =G30<=$T$12 | P30: =OR(AND(H30>=$T$4,K30<=$T$5,N30),M30) | Q30: =OR(AND(I30>=$T$10,K30<=$T$11,O30),M30)
A31: =Data!E33 | B31: =Data!G33 | C31: =Data!H33 | D31: =Data!I33 | E31: =Data!M33 | F31: =Data!O33 | G31: =E31-F31 | H31: =Data!P33 | I31: =G31+H31 | J31: =F31+G31+H31 | K31: =Data!R33 | L31: =Data!T33 | M31: =AND(E31=0,F31=0,G31=0,H31=0,I31=0,J31=0,K31=0,L31=0) | N31: =G31<=$T$6 | O31: =G31<=$T$12 | P31: =OR(AND(H31>=$T$4,K31<=$T$5,N31),M31) | Q31: =OR(AND(I31>=$T$10,K31<=$T$11,O31),M31)
A32: =Data!E34 | B32: =Data!G34 | C32: =Data!H34 | D32: =Data!I34 | E32: =Data!M34 | F32: =Data!O34 | G32: =E32-F32 | H32: =Data!P34 | I32: =G32+H32 | J32: =F32+G32+H32 | K32: =Data!R34 | L32: =Data!T34 | M32: =AND(E32=0,F32=0,G32=0,H32=0,I32=0,J32=0,K32=0,L32=0) | N32: =G32<=$T$6 | O32: =G32<=$T$12 | P32: =OR(AND(H32>=$T$4,K32<=$T$5,N32),M32) | Q32: =OR(AND(I32>=$T$10,K32<=$T$11,O32),M32)
A33: =Data!E35 | B33: =Data!G35 | C33: =Data!H35 | D33: =Data!I35 | E33: =Data!M35 | F33: =Data!O35 | G33: =E33-F33 | H33: =Data!P35 | I33: =G33+H33 | J33: =F33+G33+H33 | K33: =Data!R35 | L33: =Data!T35 | M33: =AND(E33=0,F33=0,G33=0,H33=0,I33=0,J33=0,K33=0,L33=0) | N33: =G33<=$T$6 | O33: =G33<=$T$12 | P33: =OR(AND(H33>=$T$4,K33<=$T$5,N33),M33) | Q33: =OR(AND(I33>=$T$10,K33<=$T$11,O33),M33)
A34: =Data!E36 | B34: =Data!G36 | C34: =Data!H36 | D34: =Data!I36 | E34: =Data!M36 | F34: =Data!O36 | G34: =E34-F34 | H34: =Data!P36 | I34: =G34+H34 | J34: =F34+G34+H34 | K34: =Data!R36 | L34: =Data!T36 | M34: =AND(E34=0,F34=0,G34=0,H34=0,I34=0,J34=0,K34=0,L34=0) | N34: =G34<=$T$6 | O34: =G34<=$T$12 | P34: =OR(AND(H34>=$T$4,K34<=$T$5,N34),M34) | Q34: =OR(AND(I34>=$T$10,K34<=$T$11,O34),M34)
... A36: =Data!E38 | B36: =Data!G38 | C36: =Data!H38 | D36: =Data!I38 | E36: =Data!M38 | F36: =Data!O38 | G36: =E36-F36 | H36: =Data!P38 | I36: =G36+H36 | J36: =F36+G36+H36 | K36: =Data!R38 | L36: =Data!T38 | M36: =AND(E36=0,F36=0,G36=0,H36=0,I36=0,J36=0,K36=0,L36=0) | N36: =G36<=$T$6 | O36: =G36<=$T$12 | P36: =OR(AND(H36>=$T$4,K36<=$T$5,N36),M36) | Q36: =OR(AND(I36>=$T$10,K36<=$T$11,O36),M36)
A37: =Data!E40 | B37: =Data!G40 | C37: =Data!H40 | D37: =Data!I40 | E37: =Data!M40 | F37: =Data!O40 | G37: =E37-F37 | H37: =Data!P40 | I37: =G37+H37 | J37: =F37+G37+H37 | K37: =Data!R40 | L37: =Data!T40 | M37: =AND(E37=0,F37=0,G37=0,H37=0,I37=0,J37=0,K37=0,L37=0) | N37: =G37<=$T$6 | O37: =G37<=$T$12 | P37: =OR(AND(H37>=$T$4,K37<=$T$5,N37),M37) | Q37: =OR(AND(I37>=$T$10,K37<=$T$11,O37),M37)
A38: =Data!E41 | B38: =Data!G41 | C38: =Data!H41 | D38: =Data!I41 | E38: =Data!M41 | F38: =Data!O41 | G38: =E38-F38 | H38: =Data!P41 | I38: =G38+H38 | J38: =F38+G38+H38 | K38: =Data!R41 | L38: =Data!T41 | M38: =AND(E38=0,F38=0,G38=0,H38=0,I38=0,J38=0,K38=0,L38=0) | N38: =G38<=$T$6 | O38: =G38<=$T$12 | P38: =OR(AND(H38>=$T$4,K38<=$T$5,N38),M38) | Q38: =OR(AND(I38>=$T$10,K38<=$T$11,O38),M38)
A39: =Data!E42 | B39: =Data!G42 | C39: =Data!H42 | D39: =Data!I42 | E39: =Data!M42 | F39: =Data!O42 | G39: =E39-F39 | H39: =Data!P42 | I39: =G39+H39 | J39: =F39+G39+H39 | K39: =Data!R42 | L39: =Data!T42 | M39: =AND(E39=0,F39=0,G39=0,H39=0,I39=0,J39=0,K39=0,L39=0) | N39: =G39<=$T$6 | O39: =G39<=$T$12 | P39: =OR(AND(H39>=$T$4,K39<=$T$5,N39),M39) | Q39: =OR(AND(I39>=$T$10,K39<=$T$11,O39),M39)
A40: =Data!E43 | B40: =Data!G43 | C40: =Data!H43 | D40: =Data!I43 | E40: =Data!M43 | F40: =Data!O43 | G40: =E40-F40 | H40: =Data!P43 | I40: =G40+H40 | J40: =F40+G40+H40 | K40: =Data!R43 | L40: =Data!T43 | M40: =AND(E40=0,F40=0,G40=0,H40=0,I40=0,J40=0,K40=0,L40=0) | N40: =G40<=$T$6 | O40: =G40<=$T$12 | P40: =OR(AND(H40>=$T$4,K40<=$T$5,N40),M40) | Q40: =OR(AND(I40>=$T$10,K40<=$T$11,O40),M40)
A41: =Data!E44 | B41: =Data!G44 | C41: =Data!H44 | D41: =Data!I44 | E41: =Data!M44 | F41: =Data!O44 | G41: =E41-F41 | H41: =Data!P44 | I41: =G41+H41 | J41: =F41+G41+H41 | K41: =Data!R44 | L41: =Data!T44 | M41: =AND(E41=0,F41=0,G41=0,H41=0,I41=0,J41=0,K41=0,L41=0) | N41: =G41<=$T$6 | O41: =G41<=$T$12 | P41: =OR(AND(H41>=$T$4,K41<=$T$5,N41),M41) | Q41: =OR(AND(I41>=$T$10,K41<=$T$11,O41),M41)
...

Sheet byIntensity
E2: min_kick_ms | F2: max_kick_ms | G2: min_on_ms | H2: max_on_ms | I2: min_real_on_ms | J2: max_real_on_ms | O2: min_kick_ms | P2: max_kick_ms | Q2: min_on_ms | R2: max_on_ms | S2: min_real_on_ms | T2: max_real_on_ms | Y2: min_kick_ms | Z2: max_kick_ms | AA2: min_on_ms | AB2: max_on_ms | AC2: min_real_on_ms | AD2: max_real_on_ms
B3: %6, 4.2V, %100 | D3: on_ms | E3: =_xlfn.MINIFS(Data_new!$D$2:$D$2639,Data_new!$A$2:$A$2639,4.2,Data_new!$B$2:$B$2639,VALUE(MID($B$3,2,FIND(",",$B$3)-2)),Data_new!$C$2:$C$2639,100,Data_new!$P$2:$P$2639,TRUE) | F3: =_xlfn.MAXIFS(Data_new!$D$2:$D$2639,Data_new!$A$2:$A$2639,4.2,Data_new!$B$2:$B$2639,VALUE(MID($B$3,2,FIND(",",$B$3)-2)),Data_new!$C$2:$C$2639,100,Data_new!$P$2:$P$2639,TRUE) | G3: =_xlfn.MINIFS(Data_new!$H$2:$H$2639,Data_new!$A$2:$A$2639,4.2,Data_new!$B$2:$B$2639,VALUE(MID($B$3,2,FIND(",",$B$3)-2)),Data_new!$C$2:$C$2639,100,Data_new!$P$2:$P$2639,TRUE) | H3: =_xlfn.MAXIFS(Data_new!$H$2:$H$2639,Data_new!$A$2:$A$2639,4.2,Data_new!$B$2:$B$2639,VALUE(MID($B$3,2,FIND(",",$B$3)-2)),Data_new!$C$2:$C$2639,100,Data_new!$P$2:$P$2639,TRUE) | I3: nan | J3: nan | L3: %6, 4.2V, %80 | N3: on_ms | O3: =_xlfn.MINIFS(Data_new!$D$2:$D$2639,Data_new!$A$2:$A$2639,4.2,Data_new!$B$2:$B$2639,VALUE(MID($L$3,2,FIND(",",$L$3)-2)),Data_new!$C$2:$C$2639,80,Data_new!$P$2:$P$2639,TRUE) | P3: =_xlfn.MAXIFS(Data_new!$D$2:$D$2639,Data_new!$A$2:$A$2639,4.2,Data_new!$B$2:$B$2639,VALUE(MID($L$3,2,FIND(",",$L$3)-2)),Data_new!$C$2:$C$2639,80,Data_new!$P$2:$P$2639,TRUE) | Q3: =_xlfn.MINIFS(Data_new!$H$2:$H$2639,Data_new!$A$2:$A$2639,4.2,Data_new!$B$2:$B$2639,VALUE(MID($L$3,2,FIND(",",$L$3)-2)),Data_new!$C$2:$C$2639,80,Data_new!$P$2:$P$2639,TRUE) | R3: =_xlfn.MAXIFS(Data_new!$H$2:$H$2639,Data_new!$A$2:$A$2639,4.2,Data_new!$B$2:$B$2639,VALUE(MID($L$3,2,FIND(",",$L$3)-2)),Data_new!$C$2:$C$2639,80,Data_new!$P$2:$P$2639,TRUE) | S3: nan | T3: nan | V3: %6, 4.2V, %60 | X3: on_ms | Y3: =_xlfn.MINIFS(Data_new!$D$2:$D$2639,Data_new!$A$2:$A$2639,4.2,Data_new!$B$2:$B$2639,VALUE(MID($V$3,2,FIND(",",$V$3)-2)),Data_new!$C$2:$C$2639,60,Data_new!$P$2:$P$2639,TRUE) | Z3: =_xlfn.MAXIFS(Data_new!$D$2:$D$2639,Data_new!$A$2:$A$2639,4.2,Data_new!$B$2:$B$2639,VALUE(MID($V$3,2,FIND(",",$V$3)-2)),Data_new!$C$2:$C$2639,60,Data_new!$P$2:$P$2639,TRUE) | AA3: =_xlfn.MINIFS(Data_new!$H$2:$H$2639,Data_new!$A$2:$A$2639,4.2,Data_new!$B$2:$B$2639,VALUE(MID($V$3,2,FIND(",",$V$3)-2)),Data_new!$C$2:$C$2639,60,Data_new!$P$2:$P$2639,TRUE) | AB3: =_xlfn.MAXIFS(Data_new!$H$2:$H$2639,Data_new!$A$2:$A$2639,4.2,Data_new!$B$2:$B$2639,VALUE(MID($V$3,2,FIND(",",$V$3)-2)),Data_new!$C$2:$C$2639,60,Data_new!$P$2:$P$2639,TRUE) | AC3: nan | AD3: nan
D4: real_on_ms | E4: =_xlfn.MINIFS(Data_new!$D$2:$D$2639,Data_new!$A$2:$A$2639,4.2,Data_new!$B$2:$B$2639,VALUE(MID($B$3,2,FIND(",",$B$3)-2)),Data_new!$C$2:$C$2639,100,Data_new!$Q$2:$Q$2639,TRUE) | F4: =_xlfn.MAXIFS(Data_new!$D$2:$D$2639,Data_new!$A$2:$A$2639,4.2,Data_new!$B$2:$B$2639,VALUE(MID($B$3,2,FIND(",",$B$3)-2)),Data_new!$C$2:$C$2639,100,Data_new!$Q$2:$Q$2639,TRUE) | G4: nan | H4: nan | I4: =_xlfn.MINIFS(Data_new!$I$2:$I$2639,Data_new!$A$2:$A$2639,4.2,Data_new!$B$2:$B$2639,VALUE(MID($B$3,2,FIND(",",$B$3)-2)),Data_new!$C$2:$C$2639,100,Data_new!$Q$2:$Q$2639,TRUE) | J4: =_xlfn.MAXIFS(Data_new!$I$2:$I$2639,Data_new!$A$2:$A$2639,4.2,Data_new!$B$2:$B$2639,VALUE(MID($B$3,2,FIND(",",$B$3)-2)),Data_new!$C$2:$C$2639,100,Data_new!$Q$2:$Q$2639,TRUE) | N4: real_on_ms | O4: =_xlfn.MINIFS(Data_new!$D$2:$D$2639,Data_new!$A$2:$A$2639,4.2,Data_new!$B$2:$B$2639,VALUE(MID($L$3,2,FIND(",",$L$3)-2)),Data_new!$C$2:$C$2639,80,Data_new!$Q$2:$Q$2639,TRUE) | P4: =_xlfn.MAXIFS(Data_new!$D$2:$D$2639,Data_new!$A$2:$A$2639,4.2,Data_new!$B$2:$B$2639,VALUE(MID($L$3,2,FIND(",",$L$3)-2)),Data_new!$C$2:$C$2639,80,Data_new!$Q$2:$Q$2639,TRUE) | Q4: nan | R4: nan | S4: =_xlfn.MINIFS(Data_new!$I$2:$I$2639,Data_new!$A$2:$A$2639,4.2,Data_new!$B$2:$B$2639,VALUE(MID($L$3,2,FIND(",",$L$3)-2)),Data_new!$C$2:$C$2639,80,Data_new!$Q$2:$Q$2639,TRUE) | T4: =_xlfn.MAXIFS(Data_new!$I$2:$I$2639,Data_new!$A$2:$A$2639,4.2,Data_new!$B$2:$B$2639,VALUE(MID($L$3,2,FIND(",",$L$3)-2)),Data_new!$C$2:$C$2639,80,Data_new!$Q$2:$Q$2639,TRUE) | X4: real_on_ms | Y4: =_xlfn.MINIFS(Data_new!$D$2:$D$2639,Data_new!$A$2:$A$2639,4.2,Data_new!$B$2:$B$2639,VALUE(MID($V$3,2,FIND(",",$V$3)-2)),Data_new!$C$2:$C$2639,60,Data_new!$Q$2:$Q$2639,TRUE) | Z4: =_xlfn.MAXIFS(Data_new!$D$2:$D$2639,Data_new!$A$2:$A$2639,4.2,Data_new!$B$2:$B$2639,VALUE(MID($V$3,2,FIND(",",$V$3)-2)),Data_new!$C$2:$C$2639,60,Data_new!$Q$2:$Q$2639,TRUE) | AA4: nan | AB4: nan | AC4: =_xlfn.MINIFS(Data_new!$I$2:$I$2639,Data_new!$A$2:$A$2639,4.2,Data_new!$B$2:$B$2639,VALUE(MID($V$3,2,FIND(",",$V$3)-2)),Data_new!$C$2:$C$2639,60,Data_new!$Q$2:$Q$2639,TRUE) | AD4: =_xlfn.MAXIFS(Data_new!$I$2:$I$2639,Data_new!$A$2:$A$2639,4.2,Data_new!$B$2:$B$2639,VALUE(MID($V$3,2,FIND(",",$V$3)-2)),Data_new!$C$2:$C$2639,60,Data_new!$Q$2:$Q$2639,TRUE)
B6: %7, 4.2V, %100 | D6: on_ms | E6: =_xlfn.MINIFS(Data_new!$D$2:$D$2639,Data_new!$A$2:$A$2639,4.2,Data_new!$B$2:$B$2639,VALUE(MID($B$6,2,FIND(",",$B$6)-2)),Data_new!$C$2:$C$2639,100,Data_new!$P$2:$P$2639,TRUE) | F6: =_xlfn.MAXIFS(Data_new!$D$2:$D$2639,Data_new!$A$2:$A$2639,4.2,Data_new!$B$2:$B$2639,VALUE(MID($B$6,2,FIND(",",$B$6)-2)),Data_new!$C$2:$C$2639,100,Data_new!$P$2:$P$2639,TRUE) | G6: =_xlfn.MINIFS(Data_new!$H$2:$H$2639,Data_new!$A$2:$A$2639,4.2,Data_new!$B$2:$B$2639,VALUE(MID($B$6,2,FIND(",",$B$6)-2)),Data_new!$C$2:$C$2639,100,Data_new!$P$2:$P$2639,TRUE) | H6: =_xlfn.MAXIFS(Data_new!$H$2:$H$2639,Data_new!$A$2:$A$2639,4.2,Data_new!$B$2:$B$2639,VALUE(MID($B$6,2,FIND(",",$B$6)-2)),Data_new!$C$2:$C$2639,100,Data_new!$P$2:$P$2639,TRUE) | I6: nan | J6: nan | L6: %7, 4.2V, %80 | N6: on_ms | O6: =_xlfn.MINIFS(Data_new!$D$2:$D$2639,Data_new!$A$2:$A$2639,4.2,Data_new!$B$2:$B$2639,VALUE(MID($L$6,2,FIND(",",$L$6)-2)),Data_new!$C$2:$C$2639,80,Data_new!$P$2:$P$2639,TRUE) | P6: =_xlfn.MAXIFS(Data_new!$D$2:$D$2639,Data_new!$A$2:$A$2639,4.2,Data_new!$B$2:$B$2639,VALUE(MID($L$6,2,FIND(",",$L$6)-2)),Data_new!$C$2:$C$2639,80,Data_new!$P$2:$P$2639,TRUE) | Q6: =_xlfn.MINIFS(Data_new!$H$2:$H$2639,Data_new!$A$2:$A$2639,4.2,Data_new!$B$2:$B$2639,VALUE(MID($L$6,2,FIND(",",$L$6)-2)),Data_new!$C$2:$C$2639,80,Data_new!$P$2:$P$2639,TRUE) | R6: =_xlfn.MAXIFS(Data_new!$H$2:$H$2639,Data_new!$A$2:$A$2639,4.2,Data_new!$B$2:$B$2639,VALUE(MID($L$6,2,FIND(",",$L$6)-2)),Data_new!$C$2:$C$2639,80,Data_new!$P$2:$P$2639,TRUE) | S6: nan | T6: nan | V6: %7, 4.2V, %60 | X6: on_ms | Y6: =_xlfn.MINIFS(Data_new!$D$2:$D$2639,Data_new!$A$2:$A$2639,4.2,Data_new!$B$2:$B$2639,VALUE(MID($V$6,2,FIND(",",$V$6)-2)),Data_new!$C$2:$C$2639,60,Data_new!$P$2:$P$2639,TRUE) | Z6: =_xlfn.MAXIFS(Data_new!$D$2:$D$2639,Data_new!$A$2:$A$2639,4.2,Data_new!$B$2:$B$2639,VALUE(MID($V$6,2,FIND(",",$V$6)-2)),Data_new!$C$2:$C$2639,60,Data_new!$P$2:$P$2639,TRUE) | AA6: =_xlfn.MINIFS(Data_new!$H$2:$H$2639,Data_new!$A$2:$A$2639,4.2,Data_new!$B$2:$B$2639,VALUE(MID($V$6,2,FIND(",",$V$6)-2)),Data_new!$C$2:$C$2639,60,Data_new!$P$2:$P$2639,TRUE) | AB6: =_xlfn.MAXIFS(Data_new!$H$2:$H$2639,Data_new!$A$2:$A$2639,4.2,Data_new!$B$2:$B$2639,VALUE(MID($V$6,2,FIND(",",$V$6)-2)),Data_new!$C$2:$C$2639,60,Data_new!$P$2:$P$2639,TRUE) | AC6: nan | AD6: nan
D7: real_on_ms | E7: =_xlfn.MINIFS(Data_new!$D$2:$D$2639,Data_new!$A$2:$A$2639,4.2,Data_new!$B$2:$B$2639,VALUE(MID($B$6,2,FIND(",",$B$6)-2)),Data_new!$C$2:$C$2639,100,Data_new!$Q$2:$Q$2639,TRUE) | F7: =_xlfn.MAXIFS(Data_new!$D$2:$D$2639,Data_new!$A$2:$A$2639,4.2,Data_new!$B$2:$B$2639,VALUE(MID($B$6,2,FIND(",",$B$6)-2)),Data_new!$C$2:$C$2639,100,Data_new!$Q$2:$Q$2639,TRUE) | G7: nan | H7: nan | I7: =_xlfn.MINIFS(Data_new!$I$2:$I$2639,Data_new!$A$2:$A$2639,4.2,Data_new!$B$2:$B$2639,VALUE(MID($B$6,2,FIND(",",$B$6)-2)),Data_new!$C$2:$C$2639,100,Data_new!$Q$2:$Q$2639,TRUE) | J7: =_xlfn.MAXIFS(Data_new!$I$2:$I$2639,Data_new!$A$2:$A$2639,4.2,Data_new!$B$2:$B$2639,VALUE(MID($B$6,2,FIND(",",$B$6)-2)),Data_new!$C$2:$C$2639,100,Data_new!$Q$2:$Q$2639,TRUE) | N7: real_on_ms | O7: =_xlfn.MINIFS(Data_new!$D$2:$D$2639,Data_new!$A$2:$A$2639,4.2,Data_new!$B$2:$B$2639,VALUE(MID($L$6,2,FIND(",",$L$6)-2)),Data_new!$C$2:$C$2639,80,Data_new!$Q$2:$Q$2639,TRUE) | P7: =_xlfn.MAXIFS(Data_new!$D$2:$D$2639,Data_new!$A$2:$A$2639,4.2,Data_new!$B$2:$B$2639,VALUE(MID($L$6,2,FIND(",",$L$6)-2)),Data_new!$C$2:$C$2639,80,Data_new!$Q$2:$Q$2639,TRUE) | Q7: nan | R7: nan | S7: =_xlfn.MINIFS(Data_new!$I$2:$I$2639,Data_new!$A$2:$A$2639,4.2,Data_new!$B$2:$B$2639,VALUE(MID($L$6,2,FIND(",",$L$6)-2)),Data_new!$C$2:$C$2639,80,Data_new!$Q$2:$Q$2639,TRUE) | T7: =_xlfn.MAXIFS(Data_new!$I$2:$I$2639,Data_new!$A$2:$A$2639,4.2,Data_new!$B$2:$B$2639,VALUE(MID($L$6,2,FIND(",",$L$6)-2)),Data_new!$C$2:$C$2639,80,Data_new!$Q$2:$Q$2639,TRUE) | X7: real_on_ms | Y7: =_xlfn.MINIFS(Data_new!$D$2:$D$2639,Data_new!$A$2:$A$2639,4.2,Data_new!$B$2:$B$2639,VALUE(MID($V$6,2,FIND(",",$V$6)-2)),Data_new!$C$2:$C$2639,60,Data_new!$Q$2:$Q$2639,TRUE) | Z7: =_xlfn.MAXIFS(Data_new!$D$2:$D$2639,Data_new!$A$2:$A$2639,4.2,Data_new!$B$2:$B$2639,VALUE(MID($V$6,2,FIND(",",$V$6)-2)),Data_new!$C$2:$C$2639,60,Data_new!$Q$2:$Q$2639,TRUE) | AA7: nan | AB7: nan | AC7: =_xlfn.MINIFS(Data_new!$I$2:$I$2639,Data_new!$A$2:$A$2639,4.2,Data_new!$B$2:$B$2639,VALUE(MID($V$6,2,FIND(",",$V$6)-2)),Data_new!$C$2:$C$2639,60,Data_new!$Q$2:$Q$2639,TRUE) | AD7: =_xlfn.MAXIFS(Data_new!$I$2:$I$2639,Data_new!$A$2:$A$2639,4.2,Data_new!$B$2:$B$2639,VALUE(MID($V$6,2,FIND(",",$V$6)-2)),Data_new!$C$2:$C$2639,60,Data_new!$Q$2:$Q$2639,TRUE)
B9: %8, 4.2V, %100 | D9: on_ms | E9: =_xlfn.MINIFS(Data_new!$D$2:$D$2639,Data_new!$A$2:$A$2639,4.2,Data_new!$B$2:$B$2639,VALUE(MID($B$9,2,FIND(",",$B$9)-2)),Data_new!$C$2:$C$2639,100,Data_new!$P$2:$P$2639,TRUE) | F9: =_xlfn.MAXIFS(Data_new!$D$2:$D$2639,Data_new!$A$2:$A$2639,4.2,Data_new!$B$2:$B$2639,VALUE(MID($B$9,2,FIND(",",$B$9)-2)),Data_new!$C$2:$C$2639,100,Data_new!$P$2:$P$2639,TRUE) | G9: =_xlfn.MINIFS(Data_new!$H$2:$H$2639,Data_new!$A$2:$A$2639,4.2,Data_new!$B$2:$B$2639,VALUE(MID($B$9,2,FIND(",",$B$9)-2)),Data_new!$C$2:$C$2639,100,Data_new!$P$2:$P$2639,TRUE) | H9: =_xlfn.MAXIFS(Data_new!$H$2:$H$2639,Data_new!$A$2:$A$2639,4.2,Data_new!$B$2:$B$2639,VALUE(MID($B$9,2,FIND(",",$B$9)-2)),Data_new!$C$2:$C$2639,100,Data_new!$P$2:$P$2639,TRUE) | I9: nan | J9: nan | L9: %8, 4.2V, %80 | N9: on_ms | O9: =_xlfn.MINIFS(Data_new!$D$2:$D$2639,Data_new!$A$2:$A$2639,4.2,Data_new!$B$2:$B$2639,VALUE(MID($L$9,2,FIND(",",$L$9)-2)),Data_new!$C$2:$C$2639,80,Data_new!$P$2:$P$2639,TRUE) | P9: =_xlfn.MAXIFS(Data_new!$D$2:$D$2639,Data_new!$A$2:$A$2639,4.2,Data_new!$B$2:$B$2639,VALUE(MID($L$9,2,FIND(",",$L$9)-2)),Data_new!$C$2:$C$2639,80,Data_new!$P$2:$P$2639,TRUE) | Q9: =_xlfn.MINIFS(Data_new!$H$2:$H$2639,Data_new!$A$2:$A$2639,4.2,Data_new!$B$2:$B$2639,VALUE(MID($L$9,2,FIND(",",$L$9)-2)),Data_new!$C$2:$C$2639,80,Data_new!$P$2:$P$2639,TRUE) | R9: =_xlfn.MAXIFS(Data_new!$H$2:$H$2639,Data_new!$A$2:$A$2639,4.2,Data_new!$B$2:$B$2639,VALUE(MID($L$9,2,FIND(",",$L$9)-2)),Data_new!$C$2:$C$2639,80,Data_new!$P$2:$P$2639,TRUE) | S9: nan | T9: nan | V9: %8, 4.2V, %60 | X9: on_ms | Y9: =_xlfn.MINIFS(Data_new!$D$2:$D$2639,Data_new!$A$2:$A$2639,4.2,Data_new!$B$2:$B$2639,VALUE(MID($V$9,2,FIND(",",$V$9)-2)),Data_new!$C$2:$C$2639,60,Data_new!$P$2:$P$2639,TRUE) | Z9: =_xlfn.MAXIFS(Data_new!$D$2:$D$2639,Data_new!$A$2:$A$2639,4.2,Data_new!$B$2:$B$2639,VALUE(MID($V$9,2,FIND(",",$V$9)-2)),Data_new!$C$2:$C$2639,60,Data_new!$P$2:$P$2639,TRUE) | AA9: =_xlfn.MINIFS(Data_new!$H$2:$H$2639,Data_new!$A$2:$A$2639,4.2,Data_new!$B$2:$B$2639,VALUE(MID($V$9,2,FIND(",",$V$9)-2)),Data_new!$C$2:$C$2639,60,Data_new!$P$2:$P$2639,TRUE) | AB9: =_xlfn.MAXIFS(Data_new!$H$2:$H$2639,Data_new!$A$2:$A$2639,4.2,Data_new!$B$2:$B$2639,VALUE(MID($V$9,2,FIND(",",$V$9)-2)),Data_new!$C$2:$C$2639,60,Data_new!$P$2:$P$2639,TRUE) | AC9: nan | AD9: nan
D10: real_on_ms | E10: =_xlfn.MINIFS(Data_new!$D$2:$D$2639,Data_new!$A$2:$A$2639,4.2,Data_new!$B$2:$B$2639,VALUE(MID($B$9,2,FIND(",",$B$9)-2)),Data_new!$C$2:$C$2639,100,Data_new!$Q$2:$Q$2639,TRUE) | F10: =_xlfn.MAXIFS(Data_new!$D$2:$D$2639,Data_new!$A$2:$A$2639,4.2,Data_new!$B$2:$B$2639,VALUE(MID($B$9,2,FIND(",",$B$9)-2)),Data_new!$C$2:$C$2639,100,Data_new!$Q$2:$Q$2639,TRUE) | G10: nan | H10: nan | I10: =_xlfn.MINIFS(Data_new!$I$2:$I$2639,Data_new!$A$2:$A$2639,4.2,Data_new!$B$2:$B$2639,VALUE(MID($B$9,2,FIND(",",$B$9)-2)),Data_new!$C$2:$C$2639,100,Data_new!$Q$2:$Q$2639,TRUE) | J10: =_xlfn.MAXIFS(Data_new!$I$2:$I$2639,Data_new!$A$2:$A$2639,4.2,Data_new!$B$2:$B$2639,VALUE(MID($B$9,2,FIND(",",$B$9)-2)),Data_new!$C$2:$C$2639,100,Data_new!$Q$2:$Q$2639,TRUE) | N10: real_on_ms | O10: =_xlfn.MINIFS(Data_new!$D$2:$D$2639,Data_new!$A$2:$A$2639,4.2,Data_new!$B$2:$B$2639,VALUE(MID($L$9,2,FIND(",",$L$9)-2)),Data_new!$C$2:$C$2639,80,Data_new!$Q$2:$Q$2639,TRUE) | P10: =_xlfn.MAXIFS(Data_new!$D$2:$D$2639,Data_new!$A$2:$A$2639,4.2,Data_new!$B$2:$B$2639,VALUE(MID($L$9,2,FIND(",",$L$9)-2)),Data_new!$C$2:$C$2639,80,Data_new!$Q$2:$Q$2639,TRUE) | Q10: nan | R10: nan | S10: =_xlfn.MINIFS(Data_new!$I$2:$I$2639,Data_new!$A$2:$A$2639,4.2,Data_new!$B$2:$B$2639,VALUE(MID($L$9,2,FIND(",",$L$9)-2)),Data_new!$C$2:$C$2639,80,Data_new!$Q$2:$Q$2639,TRUE) | T10: =_xlfn.MAXIFS(Data_new!$I$2:$I$2639,Data_new!$A$2:$A$2639,4.2,Data_new!$B$2:$B$2639,VALUE(MID($L$9,2,FIND(",",$L$9)-2)),Data_new!$C$2:$C$2639,80,Data_new!$Q$2:$Q$2639,TRUE) | X10: real_on_ms | Y10: =_xlfn.MINIFS(Data_new!$D$2:$D$2639,Data_new!$A$2:$A$2639,4.2,Data_new!$B$2:$B$2639,VALUE(MID($V$9,2,FIND(",",$V$9)-2)),Data_new!$C$2:$C$2639,60,Data_new!$Q$2:$Q$2639,TRUE) | Z10: =_xlfn.MAXIFS(Data_new!$D$2:$D$2639,Data_new!$A$2:$A$2639,4.2,Data_new!$B$2:$B$2639,VALUE(MID($V$9,2,FIND(",",$V$9)-2)),Data_new!$C$2:$C$2639,60,Data_new!$Q$2:$Q$2639,TRUE) | AA10: nan | AB10: nan | AC10: =_xlfn.MINIFS(Data_new!$I$2:$I$2639,Data_new!$A$2:$A$2639,4.2,Data_new!$B$2:$B$2639,VALUE(MID($V$9,2,FIND(",",$V$9)-2)),Data_new!$C$2:$C$2639,60,Data_new!$Q$2:$Q$2639,TRUE) | AD10: =_xlfn.MAXIFS(Data_new!$I$2:$I$2639,Data_new!$A$2:$A$2639,4.2,Data_new!$B$2:$B$2639,VALUE(MID($V$9,2,FIND(",",$V$9)-2)),Data_new!$C$2:$C$2639,60,Data_new!$Q$2:$Q$2639,TRUE)
B12: %10, 4.2V, %100 | D12: on_ms | E12: =_xlfn.MINIFS(Data_new!$D$2:$D$2639,Data_new!$A$2:$A$2639,4.2,Data_new!$B$2:$B$2639,VALUE(MID($B$12,2,FIND(",",$B$12)-2)),Data_new!$C$2:$C$2639,100,Data_new!$P$2:$P$2639,TRUE) | F12: =_xlfn.MAXIFS(Data_new!$D$2:$D$2639,Data_new!$A$2:$A$2639,4.2,Data_new!$B$2:$B$2639,VALUE(MID($B$12,2,FIND(",",$B$12)-2)),Data_new!$C$2:$C$2639,100,Data_new!$P$2:$P$2639,TRUE) | G12: =_xlfn.MINIFS(Data_new!$H$2:$H$2639,Data_new!$A$2:$A$2639,4.2,Data_new!$B$2:$B$2639,VALUE(MID($B$12,2,FIND(",",$B$12)-2)),Data_new!$C$2:$C$2639,100,Data_new!$P$2:$P$2639,TRUE) | H12: =_xlfn.MAXIFS(Data_new!$H$2:$H$2639,Data_new!$A$2:$A$2639,4.2,Data_new!$B$2:$B$2639,VALUE(MID($B$12,2,FIND(",",$B$12)-2)),Data_new!$C$2:$C$2639,100,Data_new!$P$2:$P$2639,TRUE) | I12: nan | J12: nan | L12: %10, 4.2V, %80 | N12: on_ms | O12: =_xlfn.MINIFS(Data_new!$D$2:$D$2639,Data_new!$A$2:$A$2639,4.2,Data_new!$B$2:$B$2639,VALUE(MID($L$12,2,FIND(",",$L$12)-2)),Data_new!$C$2:$C$2639,80,Data_new!$P$2:$P$2639,TRUE) | P12: =_xlfn.MAXIFS(Data_new!$D$2:$D$2639,Data_new!$A$2:$A$2639,4.2,Data_new!$B$2:$B$2639,VALUE(MID($L$12,2,FIND(",",$L$12)-2)),Data_new!$C$2:$C$2639,80,Data_new!$P$2:$P$2639,TRUE) | Q12: =_xlfn.MINIFS(Data_new!$H$2:$H$2639,Data_new!$A$2:$A$2639,4.2,Data_new!$B$2:$B$2639,VALUE(MID($L$12,2,FIND(",",$L$12)-2)),Data_new!$C$2:$C$2639,80,Data_new!$P$2:$P$2639,TRUE) | R12: =_xlfn.MAXIFS(Data_new!$H$2:$H$2639,Data_new!$A$2:$A$2639,4.2,Data_new!$B$2:$B$2639,VALUE(MID($L$12,2,FIND(",",$L$12)-2)),Data_new!$C$2:$C$2639,80,Data_new!$P$2:$P$2639,TRUE) | S12: nan | T12: nan | V12: %10, 4.2V, %60 | X12: on_ms | Y12: =_xlfn.MINIFS(Data_new!$D$2:$D$2639,Data_new!$A$2:$A$2639,4.2,Data_new!$B$2:$B$2639,VALUE(MID($V$12,2,FIND(",",$V$12)-2)),Data_new!$C$2:$C$2639,60,Data_new!$P$2:$P$2639,TRUE) | Z12: =_xlfn.MAXIFS(Data_new!$D$2:$D$2639,Data_new!$A$2:$A$2639,4.2,Data_new!$B$2:$B$2639,VALUE(MID($V$12,2,FIND(",",$V$12)-2)),Data_new!$C$2:$C$2639,60,Data_new!$P$2:$P$2639,TRUE) | AA12: =_xlfn.MINIFS(Data_new!$H$2:$H$2639,Data_new!$A$2:$A$2639,4.2,Data_new!$B$2:$B$2639,VALUE(MID($V$12,2,FIND(",",$V$12)-2)),Data_new!$C$2:$C$2639,60,Data_new!$P$2:$P$2639,TRUE) | AB12: =_xlfn.MAXIFS(Data_new!$H$2:$H$2639,Data_new!$A$2:$A$2639,4.2,Data_new!$B$2:$B$2639,VALUE(MID($V$12,2,FIND(",",$V$12)-2)),Data_new!$C$2:$C$2639,60,Data_new!$P$2:$P$2639,TRUE) | AC12: nan | AD12: nan
D13: real_on_ms | E13: =_xlfn.MINIFS(Data_new!$D$2:$D$2639,Data_new!$A$2:$A$2639,4.2,Data_new!$B$2:$B$2639,VALUE(MID($B$12,2,FIND(",",$B$12)-2)),Data_new!$C$2:$C$2639,100,Data_new!$Q$2:$Q$2639,TRUE) | F13: =_xlfn.MAXIFS(Data_new!$D$2:$D$2639,Data_new!$A$2:$A$2639,4.2,Data_new!$B$2:$B$2639,VALUE(MID($B$12,2,FIND(",",$B$12)-2)),Data_new!$C$2:$C$2639,100,Data_new!$Q$2:$Q$2639,TRUE) | G13: nan | H13: nan | I13: =_xlfn.MINIFS(Data_new!$I$2:$I$2639,Data_new!$A$2:$A$2639,4.2,Data_new!$B$2:$B$2639,VALUE(MID($B$12,2,FIND(",",$B$12)-2)),Data_new!$C$2:$C$2639,100,Data_new!$Q$2:$Q$2639,TRUE) | J13: =_xlfn.MAXIFS(Data_new!$I$2:$I$2639,Data_new!$A$2:$A$2639,4.2,Data_new!$B$2:$B$2639,VALUE(MID($B$12,2,FIND(",",$B$12)-2)),Data_new!$C$2:$C$2639,100,Data_new!$Q$2:$Q$2639,TRUE) | N13: real_on_ms | O13: =_xlfn.MINIFS(Data_new!$D$2:$D$2639,Data_new!$A$2:$A$2639,4.2,Data_new!$B$2:$B$2639,VALUE(MID($L$12,2,FIND(",",$L$12)-2)),Data_new!$C$2:$C$2639,80,Data_new!$Q$2:$Q$2639,TRUE) | P13: =_xlfn.MAXIFS(Data_new!$D$2:$D$2639,Data_new!$A$2:$A$2639,4.2,Data_new!$B$2:$B$2639,VALUE(MID($L$12,2,FIND(",",$L$12)-2)),Data_new!$C$2:$C$2639,80,Data_new!$Q$2:$Q$2639,TRUE) | Q13: nan | R13: nan | S13: =_xlfn.MINIFS(Data_new!$I$2:$I$2639,Data_new!$A$2:$A$2639,4.2,Data_new!$B$2:$B$2639,VALUE(MID($L$12,2,FIND(",",$L$12)-2)),Data_new!$C$2:$C$2639,80,Data_new!$Q$2:$Q$2639,TRUE) | T13: =_xlfn.MAXIFS(Data_new!$I$2:$I$2639,Data_new!$A$2:$A$2639,4.2,Data_new!$B$2:$B$2639,VALUE(MID($L$12,2,FIND(",",$L$12)-2)),Data_new!$C$2:$C$2639,80,Data_new!$Q$2:$Q$2639,TRUE) | X13: real_on_ms | Y13: =_xlfn.MINIFS(Data_new!$D$2:$D$2639,Data_new!$A$2:$A$2639,4.2,Data_new!$B$2:$B$2639,VALUE(MID($V$12,2,FIND(",",$V$12)-2)),Data_new!$C$2:$C$2639,60,Data_new!$Q$2:$Q$2639,TRUE) | Z13: =_xlfn.MAXIFS(Data_new!$D$2:$D$2639,Data_new!$A$2:$A$2639,4.2,Data_new!$B$2:$B$2639,VALUE(MID($V$12,2,FIND(",",$V$12)-2)),Data_new!$C$2:$C$2639,60,Data_new!$Q$2:$Q$2639,TRUE) | AA13: nan | AB13: nan | AC13: =_xlfn.MINIFS(Data_new!$I$2:$I$2639,Data_new!$A$2:$A$2639,4.2,Data_new!$B$2:$B$2639,VALUE(MID($V$12,2,FIND(",",$V$12)-2)),Data_new!$C$2:$C$2639,60,Data_new!$Q$2:$Q$2639,TRUE) | AD13: =_xlfn.MAXIFS(Data_new!$I$2:$I$2639,Data_new!$A$2:$A$2639,4.2,Data_new!$B$2:$B$2639,VALUE(MID($V$12,2,FIND(",",$V$12)-2)),Data_new!$C$2:$C$2639,60,Data_new!$Q$2:$Q$2639,TRUE)
B15: %15, 4.2V, %100 | D15: on_ms | E15: =_xlfn.MINIFS(Data_new!$D$2:$D$2639,Data_new!$A$2:$A$2639,4.2,Data_new!$B$2:$B$2639,VALUE(MID($B$15,2,FIND(",",$B$15)-2)),Data_new!$C$2:$C$2639,100,Data_new!$P$2:$P$2639,TRUE) | F15: =_xlfn.MAXIFS(Data_new!$D$2:$D$2639,Data_new!$A$2:$A$2639,4.2,Data_new!$B$2:$B$2639,VALUE(MID($B$15,2,FIND(",",$B$15)-2)),Data_new!$C$2:$C$2639,100,Data_new!$P$2:$P$2639,TRUE) | G15: =_xlfn.MINIFS(Data_new!$H$2:$H$2639,Data_new!$A$2:$A$2639,4.2,Data_new!$B$2:$B$2639,VALUE(MID($B$15,2,FIND(",",$B$15)-2)),Data_new!$C$2:$C$2639,100,Data_new!$P$2:$P$2639,TRUE) | H15: =_xlfn.MAXIFS(Data_new!$H$2:$H$2639,Data_new!$A$2:$A$2639,4.2,Data_new!$B$2:$B$2639,VALUE(MID($B$15,2,FIND(",",$B$15)-2)),Data_new!$C$2:$C$2639,100,Data_new!$P$2:$P$2639,TRUE) | I15: nan | J15: nan | L15: %15, 4.2V, %80 | N15: on_ms | O15: =_xlfn.MINIFS(Data_new!$D$2:$D$2639,Data_new!$A$2:$A$2639,4.2,Data_new!$B$2:$B$2639,VALUE(MID($L$15,2,FIND(",",$L$15)-2)),Data_new!$C$2:$C$2639,80,Data_new!$P$2:$P$2639,TRUE) | P15: =_xlfn.MAXIFS(Data_new!$D$2:$D$2639,Data_new!$A$2:$A$2639,4.2,Data_new!$B$2:$B$2639,VALUE(MID($L$15,2,FIND(",",$L$15)-2)),Data_new!$C$2:$C$2639,80,Data_new!$P$2:$P$2639,TRUE) | Q15: =_xlfn.MINIFS(Data_new!$H$2:$H$2639,Data_new!$A$2:$A$2639,4.2,Data_new!$B$2:$B$2639,VALUE(MID($L$15,2,FIND(",",$L$15)-2)),Data_new!$C$2:$C$2639,80,Data_new!$P$2:$P$2639,TRUE) | R15: =_xlfn.MAXIFS(Data_new!$H$2:$H$2639,Data_new!$A$2:$A$2639,4.2,Data_new!$B$2:$B$2639,VALUE(MID($L$15,2,FIND(",",$L$15)-2)),Data_new!$C$2:$C$2639,80,Data_new!$P$2:$P$2639,TRUE) | S15: nan | T15: nan | V15: %15, 4.2V, %60 | X15: on_ms | Y15: =_xlfn.MINIFS(Data_new!$D$2:$D$2639,Data_new!$A$2:$A$2639,4.2,Data_new!$B$2:$B$2639,VALUE(MID($V$15,2,FIND(",",$V$15)-2)),Data_new!$C$2:$C$2639,60,Data_new!$P$2:$P$2639,TRUE) | Z15: =_xlfn.MAXIFS(Data_new!$D$2:$D$2639,Data_new!$A$2:$A$2639,4.2,Data_new!$B$2:$B$2639,VALUE(MID($V$15,2,FIND(",",$V$15)-2)),Data_new!$C$2:$C$2639,60,Data_new!$P$2:$P$2639,TRUE) | AA15: =_xlfn.MINIFS(Data_new!$H$2:$H$2639,Data_new!$A$2:$A$2639,4.2,Data_new!$B$2:$B$2639,VALUE(MID($V$15,2,FIND(",",$V$15)-2)),Data_new!$C$2:$C$2639,60,Data_new!$P$2:$P$2639,TRUE) | AB15: =_xlfn.MAXIFS(Data_new!$H$2:$H$2639,Data_new!$A$2:$A$2639,4.2,Data_new!$B$2:$B$2639,VALUE(MID($V$15,2,FIND(",",$V$15)-2)),Data_new!$C$2:$C$2639,60,Data_new!$P$2:$P$2639,TRUE) | AC15: nan | AD15: nan
D16: real_on_ms | E16: =_xlfn.MINIFS(Data_new!$D$2:$D$2639,Data_new!$A$2:$A$2639,4.2,Data_new!$B$2:$B$2639,VALUE(MID($B$15,2,FIND(",",$B$15)-2)),Data_new!$C$2:$C$2639,100,Data_new!$Q$2:$Q$2639,TRUE) | F16: =_xlfn.MAXIFS(Data_new!$D$2:$D$2639,Data_new!$A$2:$A$2639,4.2,Data_new!$B$2:$B$2639,VALUE(MID($B$15,2,FIND(",",$B$15)-2)),Data_new!$C$2:$C$2639,100,Data_new!$Q$2:$Q$2639,TRUE) | G16: nan | H16: nan | I16: =_xlfn.MINIFS(Data_new!$I$2:$I$2639,Data_new!$A$2:$A$2639,4.2,Data_new!$B$2:$B$2639,VALUE(MID($B$15,2,FIND(",",$B$15)-2)),Data_new!$C$2:$C$2639,100,Data_new!$Q$2:$Q$2639,TRUE) | J16: =_xlfn.MAXIFS(Data_new!$I$2:$I$2639,Data_new!$A$2:$A$2639,4.2,Data_new!$B$2:$B$2639,VALUE(MID($B$15,2,FIND(",",$B$15)-2)),Data_new!$C$2:$C$2639,100,Data_new!$Q$2:$Q$2639,TRUE) | N16: real_on_ms | O16: =_xlfn.MINIFS(Data_new!$D$2:$D$2639,Data_new!$A$2:$A$2639,4.2,Data_new!$B$2:$B$2639,VALUE(MID($L$15,2,FIND(",",$L$15)-2)),Data_new!$C$2:$C$2639,80,Data_new!$Q$2:$Q$2639,TRUE) | P16: =_xlfn.MAXIFS(Data_new!$D$2:$D$2639,Data_new!$A$2:$A$2639,4.2,Data_new!$B$2:$B$2639,VALUE(MID($L$15,2,FIND(",",$L$15)-2)),Data_new!$C$2:$C$2639,80,Data_new!$Q$2:$Q$2639,TRUE) | Q16: nan | R16: nan | S16: =_xlfn.MINIFS(Data_new!$I$2:$I$2639,Data_new!$A$2:$A$2639,4.2,Data_new!$B$2:$B$2639,VALUE(MID($L$15,2,FIND(",",$L$15)-2)),Data_new!$C$2:$C$2639,80,Data_new!$Q$2:$Q$2639,TRUE) | T16: =_xlfn.MAXIFS(Data_new!$I$2:$I$2639,Data_new!$A$2:$A$2639,4.2,Data_new!$B$2:$B$2639,VALUE(MID($L$15,2,FIND(",",$L$15)-2)),Data_new!$C$2:$C$2639,80,Data_new!$Q$2:$Q$2639,TRUE) | X16: real_on_ms | Y16: =_xlfn.MINIFS(Data_new!$D$2:$D$2639,Data_new!$A$2:$A$2639,4.2,Data_new!$B$2:$B$2639,VALUE(MID($V$15,2,FIND(",",$V$15)-2)),Data_new!$C$2:$C$2639,60,Data_new!$Q$2:$Q$2639,TRUE) | Z16: =_xlfn.MAXIFS(Data_new!$D$2:$D$2639,Data_new!$A$2:$A$2639,4.2,Data_new!$B$2:$B$2639,VALUE(MID($V$15,2,FIND(",",$V$15)-2)),Data_new!$C$2:$C$2639,60,Data_new!$Q$2:$Q$2639,TRUE) | AA16: nan | AB16: nan | AC16: =_xlfn.MINIFS(Data_new!$I$2:$I$2639,Data_new!$A$2:$A$2639,4.2,Data_new!$B$2:$B$2639,VALUE(MID($V$15,2,FIND(",",$V$15)-2)),Data_new!$C$2:$C$2639,60,Data_new!$Q$2:$Q$2639,TRUE) | AD16: =_xlfn.MAXIFS(Data_new!$I$2:$I$2639,Data_new!$A$2:$A$2639,4.2,Data_new!$B$2:$B$2639,VALUE(MID($V$15,2,FIND(",",$V$15)-2)),Data_new!$C$2:$C$2639,60,Data_new!$Q$2:$Q$2639,TRUE)
B18: %100, 4.2V, %100 | D18: on_ms | E18: =_xlfn.MINIFS(Data_new!$D$2:$D$2639,Data_new!$A$2:$A$2639,4.2,Data_new!$B$2:$B$2639,VALUE(MID($B$18,2,FIND(",",$B$18)-2)),Data_new!$C$2:$C$2639,100,Data_new!$P$2:$P$2639,TRUE) | F18: =_xlfn.MAXIFS(Data_new!$D$2:$D$2639,Data_new!$A$2:$A$2639,4.2,Data_new!$B$2:$B$2639,VALUE(MID($B$18,2,FIND(",",$B$18)-2)),Data_new!$C$2:$C$2639,100,Data_new!$P$2:$P$2639,TRUE) | G18: =_xlfn.MINIFS(Data_new!$H$2:$H$2639,Data_new!$A$2:$A$2639,4.2,Data_new!$B$2:$B$2639,VALUE(MID($B$18,2,FIND(",",$B$18)-2)),Data_new!$C$2:$C$2639,100,Data_new!$P$2:$P$2639,TRUE) | H18: =_xlfn.MAXIFS(Data_new!$H$2:$H$2639,Data_new!$A$2:$A$2639,4.2,Data_new!$B$2:$B$2639,VALUE(MID($B$18,2,FIND(",",$B$18)-2)),Data_new!$C$2:$C$2639,100,Data_new!$P$2:$P$2639,TRUE) | I18: nan | J18: nan | L18: %100, 4.2V, %80 | N18: on_ms | O18: =_xlfn.MINIFS(Data_new!$D$2:$D$2639,Data_new!$A$2:$A$2639,4.2,Data_new!$B$2:$B$2639,VALUE(MID($L$18,2,FIND(",",$L$18)-2)),Data_new!$C$2:$C$2639,80,Data_new!$P$2:$P$2639,TRUE) | P18: =_xlfn.MAXIFS(Data_new!$D$2:$D$2639,Data_new!$A$2:$A$2639,4.2,Data_new!$B$2:$B$2639,VALUE(MID($L$18,2,FIND(",",$L$18)-2)),Data_new!$C$2:$C$2639,80,Data_new!$P$2:$P$2639,TRUE) | Q18: =_xlfn.MINIFS(Data_new!$H$2:$H$2639,Data_new!$A$2:$A$2639,4.2,Data_new!$B$2:$B$2639,VALUE(MID($L$18,2,FIND(",",$L$18)-2)),Data_new!$C$2:$C$2639,80,Data_new!$P$2:$P$2639,TRUE) | R18: =_xlfn.MAXIFS(Data_new!$H$2:$H$2639,Data_new!$A$2:$A$2639,4.2,Data_new!$B$2:$B$2639,VALUE(MID($L$18,2,FIND(",",$L$18)-2)),Data_new!$C$2:$C$2639,80,Data_new!$P$2:$P$2639,TRUE) | S18: nan | T18: nan | V18: %100, 4.2V, %60 | X18: on_ms | Y18: =_xlfn.MINIFS(Data_new!$D$2:$D$2639,Data_new!$A$2:$A$2639,4.2,Data_new!$B$2:$B$2639,VALUE(MID($V$18,2,FIND(",",$V$18)-2)),Data_new!$C$2:$C$2639,60,Data_new!$P$2:$P$2639,TRUE) | Z18: =_xlfn.MAXIFS(Data_new!$D$2:$D$2639,Data_new!$A$2:$A$2639,4.2,Data_new!$B$2:$B$2639,VALUE(MID($V$18,2,FIND(",",$V$18)-2)),Data_new!$C$2:$C$2639,60,Data_new!$P$2:$P$2639,TRUE) | AA18: =_xlfn.MINIFS(Data_new!$H$2:$H$2639,Data_new!$A$2:$A$2639,4.2,Data_new!$B$2:$B$2639,VALUE(MID($V$18,2,FIND(",",$V$18)-2)),Data_new!$C$2:$C$2639,60,Data_new!$P$2:$P$2639,TRUE) | AB18: =_xlfn.MAXIFS(Data_new!$H$2:$H$2639,Data_new!$A$2:$A$2639,4.2,Data_new!$B$2:$B$2639,VALUE(MID($V$18,2,FIND(",",$V$18)-2)),Data_new!$C$2:$C$2639,60,Data_new!$P$2:$P$2639,TRUE) | AC18: nan | AD18: nan
D19: real_on_ms | E19: =_xlfn.MINIFS(Data_new!$D$2:$D$2639,Data_new!$A$2:$A$2639,4.2,Data_new!$B$2:$B$2639,VALUE(MID($B$18,2,FIND(",",$B$18)-2)),Data_new!$C$2:$C$2639,100,Data_new!$Q$2:$Q$2639,TRUE) | F19: =_xlfn.MAXIFS(Data_new!$D$2:$D$2639,Data_new!$A$2:$A$2639,4.2,Data_new!$B$2:$B$2639,VALUE(MID($B$18,2,FIND(",",$B$18)-2)),Data_new!$C$2:$C$2639,100,Data_new!$Q$2:$Q$2639,TRUE) | G19: nan | H19: nan | I19: =_xlfn.MINIFS(Data_new!$I$2:$I$2639,Data_new!$A$2:$A$2639,4.2,Data_new!$B$2:$B$2639,VALUE(MID($B$18,2,FIND(",",$B$18)-2)),Data_new!$C$2:$C$2639,100,Data_new!$Q$2:$Q$2639,TRUE) | J19: =_xlfn.MAXIFS(Data_new!$I$2:$I$2639,Data_new!$A$2:$A$2639,4.2,Data_new!$B$2:$B$2639,VALUE(MID($B$18,2,FIND(",",$B$18)-2)),Data_new!$C$2:$C$2639,100,Data_new!$Q$2:$Q$2639,TRUE) | N19: real_on_ms | O19: =_xlfn.MINIFS(Data_new!$D$2:$D$2639,Data_new!$A$2:$A$2639,4.2,Data_new!$B$2:$B$2639,VALUE(MID($L$18,2,FIND(",",$L$18)-2)),Data_new!$C$2:$C$2639,80,Data_new!$Q$2:$Q$2639,TRUE) | P19: =_xlfn.MAXIFS(Data_new!$D$2:$D$2639,Data_new!$A$2:$A$2639,4.2,Data_new!$B$2:$B$2639,VALUE(MID($L$18,2,FIND(",",$L$18)-2)),Data_new!$C$2:$C$2639,80,Data_new!$Q$2:$Q$2639,TRUE) | Q19: nan | R19: nan | S19: =_xlfn.MINIFS(Data_new!$I$2:$I$2639,Data_new!$A$2:$A$2639,4.2,Data_new!$B$2:$B$2639,VALUE(MID($L$18,2,FIND(",",$L$18)-2)),Data_new!$C$2:$C$2639,80,Data_new!$Q$2:$Q$2639,TRUE) | T19: =_xlfn.MAXIFS(Data_new!$I$2:$I$2639,Data_new!$A$2:$A$2639,4.2,Data_new!$B$2:$B$2639,VALUE(MID($L$18,2,FIND(",",$L$18)-2)),Data_new!$C$2:$C$2639,80,Data_new!$Q$2:$Q$2639,TRUE) | X19: real_on_ms | Y19: =_xlfn.MINIFS(Data_new!$D$2:$D$2639,Data_new!$A$2:$A$2639,4.2,Data_new!$B$2:$B$2639,VALUE(MID($V$18,2,FIND(",",$V$18)-2)),Data_new!$C$2:$C$2639,60,Data_new!$Q$2:$Q$2639,TRUE) | Z19: =_xlfn.MAXIFS(Data_new!$D$2:$D$2639,Data_new!$A$2:$A$2639,4.2,Data_new!$B$2:$B$2639,VALUE(MID($V$18,2,FIND(",",$V$18)-2)),Data_new!$C$2:$C$2639,60,Data_new!$Q$2:$Q$2639,TRUE) | AA19: nan | AB19: nan | AC19: =_xlfn.MINIFS(Data_new!$I$2:$I$2639,Data_new!$A$2:$A$2639,4.2,Data_new!$B$2:$B$2639,VALUE(MID($V$18,2,FIND(",",$V$18)-2)),Data_new!$C$2:$C$2639,60,Data_new!$Q$2:$Q$2639,TRUE) | AD19: =_xlfn.MAXIFS(Data_new!$I$2:$I$2639,Data_new!$A$2:$A$2639,4.2,Data_new!$B$2:$B$2639,VALUE(MID($V$18,2,FIND(",",$V$18)-2)),Data_new!$C$2:$C$2639,60,Data_new!$Q$2:$Q$2639,TRUE)
E25: min_kick_ms | F25: max_kick_ms | G25: min_on_ms | H25: max_on_ms | I25: min_real_on_ms | J25: max_real_on_ms | O25: min_kick_ms | P25: max_kick_ms | Q25: min_on_ms | R25: max_on_ms | S25: min_real_on_ms | T25: max_real_on_ms | Y25: min_kick_ms | Z25: max_kick_ms | AA25: min_on_ms | AB25: max_on_ms | AC25: min_real_on_ms | AD25: max_real_on_ms
B26: %6, 3.6V, %100 | D26: on_ms | E26: =_xlfn.MINIFS(Data_new!$D$2:$D$2639,Data_new!$A$2:$A$2639,3.6,Data_new!$B$2:$B$2639,VALUE(MID($B$26,2,FIND(",",$B$26)-2)),Data_new!$C$2:$C$2639,100,Data_new!$P$2:$P$2639,TRUE) | F26: =_xlfn.MAXIFS(Data_new!$D$2:$D$2639,Data_new!$A$2:$A$2639,3.6,Data_new!$B$2:$B$2639,VALUE(MID($B$26,2,FIND(",",$B$26)-2)),Data_new!$C$2:$C$2639,100,Data_new!$P$2:$P$2639,TRUE) | G26: =_xlfn.MINIFS(Data_new!$H$2:$H$2639,Data_new!$A$2:$A$2639,3.6,Data_new!$B$2:$B$2639,VALUE(MID($B$26,2,FIND(",",$B$26)-2)),Data_new!$C$2:$C$2639,100,Data_new!$P$2:$P$2639,TRUE) | H26: =_xlfn.MAXIFS(Data_new!$H$2:$H$2639,Data_new!$A$2:$A$2639,3.6,Data_new!$B$2:$B$2639,VALUE(MID($B$26,2,FIND(",",$B$26)-2)),Data_new!$C$2:$C$2639,100,Data_new!$P$2:$P$2639,TRUE) | I26: nan | J26: nan | L26: %6, 3.6V, %80 | N26: on_ms | O26: =_xlfn.MINIFS(Data_new!$D$2:$D$2639,Data_new!$A$2:$A$2639,3.6,Data_new!$B$2:$B$2639,VALUE(MID($L$26,2,FIND(",",$L$26)-2)),Data_new!$C$2:$C$2639,80,Data_new!$P$2:$P$2639,TRUE) | P26: =_xlfn.MAXIFS(Data_new!$D$2:$D$2639,Data_new!$A$2:$A$2639,3.6,Data_new!$B$2:$B$2639,VALUE(MID($L$26,2,FIND(",",$L$26)-2)),Data_new!$C$2:$C$2639,80,Data_new!$P$2:$P$2639,TRUE) | Q26: =_xlfn.MINIFS(Data_new!$H$2:$H$2639,Data_new!$A$2:$A$2639,3.6,Data_new!$B$2:$B$2639,VALUE(MID($L$26,2,FIND(",",$L$26)-2)),Data_new!$C$2:$C$2639,80,Data_new!$P$2:$P$2639,TRUE) | R26: =_xlfn.MAXIFS(Data_new!$H$2:$H$2639,Data_new!$A$2:$A$2639,3.6,Data_new!$B$2:$B$2639,VALUE(MID($L$26,2,FIND(",",$L$26)-2)),Data_new!$C$2:$C$2639,80,Data_new!$P$2:$P$2639,TRUE) | S26: nan | T26: nan | V26: %6, 3.6V, %60 | X26: on_ms | Y26: =_xlfn.MINIFS(Data_new!$D$2:$D$2639,Data_new!$A$2:$A$2639,3.6,Data_new!$B$2:$B$2639,VALUE(MID($V$26,2,FIND(",",$V$26)-2)),Data_new!$C$2:$C$2639,60,Data_new!$P$2:$P$2639,TRUE) | Z26: =_xlfn.MAXIFS(Data_new!$D$2:$D$2639,Data_new!$A$2:$A$2639,3.6,Data_new!$B$2:$B$2639,VALUE(MID($V$26,2,FIND(",",$V$26)-2)),Data_new!$C$2:$C$2639,60,Data_new!$P$2:$P$2639,TRUE) | AA26: =_xlfn.MINIFS(Data_new!$H$2:$H$2639,Data_new!$A$2:$A$2639,3.6,Data_new!$B$2:$B$2639,VALUE(MID($V$26,2,FIND(",",$V$26)-2)),Data_new!$C$2:$C$2639,60,Data_new!$P$2:$P$2639,TRUE) | AB26: =_xlfn.MAXIFS(Data_new!$H$2:$H$2639,Data_new!$A$2:$A$2639,3.6,Data_new!$B$2:$B$2639,VALUE(MID($V$26,2,FIND(",",$V$26)-2)),Data_new!$C$2:$C$2639,60,Data_new!$P$2:$P$2639,TRUE) | AC26: nan | AD26: nan
